time 0ms: Simulator started for FCFS [Q: empty]
time 5ms: Process H arrived; added to ready queue [Q: H]
time 7ms: Process H started using the CPU for 93ms burst [Q: empty]
time 22ms: Process D arrived; added to ready queue [Q: D]
time 33ms: Process A arrived; added to ready queue [Q: D A]
time 44ms: Process F arrived; added to ready queue [Q: D A F]
time 91ms: Process B arrived; added to ready queue [Q: D A F B]
time 100ms: Process H completed a CPU burst; 82 bursts to go [Q: D A F B]
time 100ms: Process H switching out of CPU; will block on I/O until time 3592ms [Q: D A F B]
time 102ms: Process C arrived; added to ready queue [Q: D A F B C]
time 104ms: Process D started using the CPU for 137ms burst [Q: A F B C]
time 108ms: Process G arrived; added to ready queue [Q: A F B C G]
time 241ms: Process D completed a CPU burst; 79 bursts to go [Q: A F B C G]
time 241ms: Process D switching out of CPU; will block on I/O until time 1543ms [Q: A F B C G]
time 242ms: Process E arrived; added to ready queue [Q: A F B C G E]
time 245ms: Process A started using the CPU for 207ms burst [Q: F B C G E]
time 452ms: Process A completed a CPU burst; 13 bursts to go [Q: F B C G E]
time 452ms: Process A switching out of CPU; will block on I/O until time 794ms [Q: F B C G E]
time 456ms: Process F started using the CPU for 106ms burst [Q: B C G E]
time 562ms: Process F completed a CPU burst; 61 bursts to go [Q: B C G E]
time 562ms: Process F switching out of CPU; will block on I/O until time 854ms [Q: B C G E]
time 566ms: Process B started using the CPU for 70ms burst [Q: C G E]
time 636ms: Process B completed a CPU burst; 57 bursts to go [Q: C G E]
time 636ms: Process B switching out of CPU; will block on I/O until time 3218ms [Q: C G E]
time 640ms: Process C started using the CPU for 21ms burst [Q: G E]
time 661ms: Process C completed a CPU burst; 40 bursts to go [Q: G E]
time 661ms: Process C switching out of CPU; will block on I/O until time 783ms [Q: G E]
time 665ms: Process G started using the CPU for 40ms burst [Q: E]
time 705ms: Process G completed a CPU burst; 41 bursts to go [Q: E]
time 705ms: Process G switching out of CPU; will block on I/O until time 1447ms [Q: E]
time 709ms: Process E started using the CPU for 20ms burst [Q: empty]
time 729ms: Process E completed a CPU burst; 81 bursts to go [Q: empty]
time 729ms: Process E switching out of CPU; will block on I/O until time 781ms [Q: empty]
time 781ms: Process E completed I/O; added to ready queue [Q: E]
time 783ms: Process E started using the CPU for 206ms burst [Q: empty]
time 783ms: Process C completed I/O; added to ready queue [Q: C]
time 794ms: Process A completed I/O; added to ready queue [Q: C A]
time 854ms: Process F completed I/O; added to ready queue [Q: C A F]
time 989ms: Process E completed a CPU burst; 80 bursts to go [Q: C A F]
time 989ms: Process E switching out of CPU; will block on I/O until time 1251ms [Q: C A F]
time 993ms: Process C started using the CPU for 321ms burst [Q: A F]
time 1251ms: Process E completed I/O; added to ready queue [Q: A F E]
time 1314ms: Process C completed a CPU burst; 39 bursts to go [Q: A F E]
time 1314ms: Process C switching out of CPU; will block on I/O until time 1756ms [Q: A F E]
time 1318ms: Process A started using the CPU for 105ms burst [Q: F E]
time 1423ms: Process A completed a CPU burst; 12 bursts to go [Q: F E]
time 1423ms: Process A switching out of CPU; will block on I/O until time 1545ms [Q: F E]
time 1427ms: Process F started using the CPU for 36ms burst [Q: E]
time 1447ms: Process G completed I/O; added to ready queue [Q: E G]
time 1463ms: Process F completed a CPU burst; 60 bursts to go [Q: E G]
time 1463ms: Process F switching out of CPU; will block on I/O until time 5275ms [Q: E G]
time 1467ms: Process E started using the CPU for 66ms burst [Q: G]
time 1533ms: Process E completed a CPU burst; 79 bursts to go [Q: G]
time 1533ms: Process E switching out of CPU; will block on I/O until time 1835ms [Q: G]
time 1537ms: Process G started using the CPU for 74ms burst [Q: empty]
time 1543ms: Process D completed I/O; added to ready queue [Q: D]
time 1545ms: Process A completed I/O; added to ready queue [Q: D A]
time 1611ms: Process G completed a CPU burst; 40 bursts to go [Q: D A]
time 1611ms: Process G switching out of CPU; will block on I/O until time 6343ms [Q: D A]
time 1615ms: Process D started using the CPU for 34ms burst [Q: A]
time 1649ms: Process D completed a CPU burst; 78 bursts to go [Q: A]
time 1649ms: Process D switching out of CPU; will block on I/O until time 2221ms [Q: A]
time 1653ms: Process A started using the CPU for 226ms burst [Q: empty]
time 1756ms: Process C completed I/O; added to ready queue [Q: C]
time 1835ms: Process E completed I/O; added to ready queue [Q: C E]
time 1879ms: Process A completed a CPU burst; 11 bursts to go [Q: C E]
time 1879ms: Process A switching out of CPU; will block on I/O until time 3601ms [Q: C E]
time 1883ms: Process C started using the CPU for 42ms burst [Q: E]
time 1925ms: Process C completed a CPU burst; 38 bursts to go [Q: E]
time 1925ms: Process C switching out of CPU; will block on I/O until time 2547ms [Q: E]
time 1929ms: Process E started using the CPU for 11ms burst [Q: empty]
time 1940ms: Process E completed a CPU burst; 78 bursts to go [Q: empty]
time 1940ms: Process E switching out of CPU; will block on I/O until time 3172ms [Q: empty]
time 2221ms: Process D completed I/O; added to ready queue [Q: D]
time 2223ms: Process D started using the CPU for 72ms burst [Q: empty]
time 2295ms: Process D completed a CPU burst; 77 bursts to go [Q: empty]
time 2295ms: Process D switching out of CPU; will block on I/O until time 3937ms [Q: empty]
time 2547ms: Process C completed I/O; added to ready queue [Q: C]
time 2549ms: Process C started using the CPU for 54ms burst [Q: empty]
time 2603ms: Process C completed a CPU burst; 37 bursts to go [Q: empty]
time 2603ms: Process C switching out of CPU; will block on I/O until time 3255ms [Q: empty]
time 3172ms: Process E completed I/O; added to ready queue [Q: E]
time 3174ms: Process E started using the CPU for 76ms burst [Q: empty]
time 3218ms: Process B completed I/O; added to ready queue [Q: B]
time 3250ms: Process E completed a CPU burst; 77 bursts to go [Q: B]
time 3250ms: Process E switching out of CPU; will block on I/O until time 3272ms [Q: B]
time 3254ms: Process B started using the CPU for 8ms burst [Q: empty]
time 3255ms: Process C completed I/O; added to ready queue [Q: C]
time 3262ms: Process B completed a CPU burst; 56 bursts to go [Q: C]
time 3262ms: Process B switching out of CPU; will block on I/O until time 3734ms [Q: C]
time 3266ms: Process C started using the CPU for 16ms burst [Q: empty]
time 3272ms: Process E completed I/O; added to ready queue [Q: E]
time 3282ms: Process C completed a CPU burst; 36 bursts to go [Q: E]
time 3282ms: Process C switching out of CPU; will block on I/O until time 3494ms [Q: E]
time 3286ms: Process E started using the CPU for 155ms burst [Q: empty]
time 3441ms: Process E completed a CPU burst; 76 bursts to go [Q: empty]
time 3441ms: Process E switching out of CPU; will block on I/O until time 3523ms [Q: empty]
time 3494ms: Process C completed I/O; added to ready queue [Q: C]
time 3496ms: Process C started using the CPU for 121ms burst [Q: empty]
time 3523ms: Process E completed I/O; added to ready queue [Q: E]
time 3592ms: Process H completed I/O; added to ready queue [Q: E H]
time 3601ms: Process A completed I/O; added to ready queue [Q: E H A]
time 3617ms: Process C completed a CPU burst; 35 bursts to go [Q: E H A]
time 3617ms: Process C switching out of CPU; will block on I/O until time 4449ms [Q: E H A]
time 3621ms: Process E started using the CPU for 58ms burst [Q: H A]
time 3679ms: Process E completed a CPU burst; 75 bursts to go [Q: H A]
time 3679ms: Process E switching out of CPU; will block on I/O until time 3891ms [Q: H A]
time 3683ms: Process H started using the CPU for 125ms burst [Q: A]
time 3734ms: Process B completed I/O; added to ready queue [Q: A B]
time 3808ms: Process H completed a CPU burst; 81 bursts to go [Q: A B]
time 3808ms: Process H switching out of CPU; will block on I/O until time 5050ms [Q: A B]
time 3812ms: Process A started using the CPU for 64ms burst [Q: B]
time 3876ms: Process A completed a CPU burst; 10 bursts to go [Q: B]
time 3876ms: Process A switching out of CPU; will block on I/O until time 4488ms [Q: B]
time 3880ms: Process B started using the CPU for 15ms burst [Q: empty]
time 3891ms: Process E completed I/O; added to ready queue [Q: E]
time 3895ms: Process B completed a CPU burst; 55 bursts to go [Q: E]
time 3895ms: Process B switching out of CPU; will block on I/O until time 4177ms [Q: E]
time 3899ms: Process E started using the CPU for 86ms burst [Q: empty]
time 3937ms: Process D completed I/O; added to ready queue [Q: D]
time 3985ms: Process E completed a CPU burst; 74 bursts to go [Q: D]
time 3985ms: Process E switching out of CPU; will block on I/O until time 4887ms [Q: D]
time 3989ms: Process D started using the CPU for 148ms burst [Q: empty]
time 4137ms: Process D completed a CPU burst; 76 bursts to go [Q: empty]
time 4137ms: Process D switching out of CPU; will block on I/O until time 4169ms [Q: empty]
time 4169ms: Process D completed I/O; added to ready queue [Q: D]
time 4171ms: Process D started using the CPU for 396ms burst [Q: empty]
time 4177ms: Process B completed I/O; added to ready queue [Q: B]
time 4449ms: Process C completed I/O; added to ready queue [Q: B C]
time 4488ms: Process A completed I/O; added to ready queue [Q: B C A]
time 4567ms: Process D completed a CPU burst; 75 bursts to go [Q: B C A]
time 4567ms: Process D switching out of CPU; will block on I/O until time 5299ms [Q: B C A]
time 4571ms: Process B started using the CPU for 71ms burst [Q: C A]
time 4642ms: Process B completed a CPU burst; 54 bursts to go [Q: C A]
time 4642ms: Process B switching out of CPU; will block on I/O until time 4924ms [Q: C A]
time 4646ms: Process C started using the CPU for 9ms burst [Q: A]
time 4655ms: Process C completed a CPU burst; 34 bursts to go [Q: A]
time 4655ms: Process C switching out of CPU; will block on I/O until time 5117ms [Q: A]
time 4659ms: Process A started using the CPU for 44ms burst [Q: empty]
time 4703ms: Process A completed a CPU burst; 9 bursts to go [Q: empty]
time 4703ms: Process A switching out of CPU; will block on I/O until time 5355ms [Q: empty]
time 4887ms: Process E completed I/O; added to ready queue [Q: E]
time 4889ms: Process E started using the CPU for 6ms burst [Q: empty]
time 4895ms: Process E completed a CPU burst; 73 bursts to go [Q: empty]
time 4895ms: Process E switching out of CPU; will block on I/O until time 5757ms [Q: empty]
time 4924ms: Process B completed I/O; added to ready queue [Q: B]
time 4926ms: Process B started using the CPU for 69ms burst [Q: empty]
time 4995ms: Process B completed a CPU burst; 53 bursts to go [Q: empty]
time 4995ms: Process B switching out of CPU; will block on I/O until time 5547ms [Q: empty]
time 5050ms: Process H completed I/O; added to ready queue [Q: H]
time 5052ms: Process H started using the CPU for 6ms burst [Q: empty]
time 5058ms: Process H completed a CPU burst; 80 bursts to go [Q: empty]
time 5058ms: Process H switching out of CPU; will block on I/O until time 6960ms [Q: empty]
time 5117ms: Process C completed I/O; added to ready queue [Q: C]
time 5119ms: Process C started using the CPU for 46ms burst [Q: empty]
time 5165ms: Process C completed a CPU burst; 33 bursts to go [Q: empty]
time 5165ms: Process C switching out of CPU; will block on I/O until time 5297ms [Q: empty]
time 5275ms: Process F completed I/O; added to ready queue [Q: F]
time 5277ms: Process F started using the CPU for 12ms burst [Q: empty]
time 5289ms: Process F completed a CPU burst; 59 bursts to go [Q: empty]
time 5289ms: Process F switching out of CPU; will block on I/O until time 5641ms [Q: empty]
time 5297ms: Process C completed I/O; added to ready queue [Q: C]
time 5299ms: Process C started using the CPU for 137ms burst [Q: empty]
time 5299ms: Process D completed I/O; added to ready queue [Q: D]
time 5355ms: Process A completed I/O; added to ready queue [Q: D A]
time 5436ms: Process C completed a CPU burst; 32 bursts to go [Q: D A]
time 5436ms: Process C switching out of CPU; will block on I/O until time 5628ms [Q: D A]
time 5440ms: Process D started using the CPU for 363ms burst [Q: A]
time 5547ms: Process B completed I/O; added to ready queue [Q: A B]
time 5628ms: Process C completed I/O; added to ready queue [Q: A B C]
time 5641ms: Process F completed I/O; added to ready queue [Q: A B C F]
time 5757ms: Process E completed I/O; added to ready queue [Q: A B C F E]
time 5803ms: Process D completed a CPU burst; 74 bursts to go [Q: A B C F E]
time 5803ms: Process D switching out of CPU; will block on I/O until time 7465ms [Q: A B C F E]
time 5807ms: Process A started using the CPU for 110ms burst [Q: B C F E]
time 5917ms: Process A completed a CPU burst; 8 bursts to go [Q: B C F E]
time 5917ms: Process A switching out of CPU; will block on I/O until time 6549ms [Q: B C F E]
time 5921ms: Process B started using the CPU for 31ms burst [Q: C F E]
time 5952ms: Process B completed a CPU burst; 52 bursts to go [Q: C F E]
time 5952ms: Process B switching out of CPU; will block on I/O until time 7444ms [Q: C F E]
time 5956ms: Process C started using the CPU for 106ms burst [Q: F E]
time 6062ms: Process C completed a CPU burst; 31 bursts to go [Q: F E]
time 6062ms: Process C switching out of CPU; will block on I/O until time 7474ms [Q: F E]
time 6066ms: Process F started using the CPU for 91ms burst [Q: E]
time 6157ms: Process F completed a CPU burst; 58 bursts to go [Q: E]
time 6157ms: Process F switching out of CPU; will block on I/O until time 6999ms [Q: E]
time 6161ms: Process E started using the CPU for 105ms burst [Q: empty]
time 6266ms: Process E completed a CPU burst; 72 bursts to go [Q: empty]
time 6266ms: Process E switching out of CPU; will block on I/O until time 7788ms [Q: empty]
time 6343ms: Process G completed I/O; added to ready queue [Q: G]
time 6345ms: Process G started using the CPU for 4ms burst [Q: empty]
time 6349ms: Process G completed a CPU burst; 39 bursts to go [Q: empty]
time 6349ms: Process G switching out of CPU; will block on I/O until time 7511ms [Q: empty]
time 6549ms: Process A completed I/O; added to ready queue [Q: A]
time 6551ms: Process A started using the CPU for 4ms burst [Q: empty]
time 6555ms: Process A completed a CPU burst; 7 bursts to go [Q: empty]
time 6555ms: Process A switching out of CPU; will block on I/O until time 6627ms [Q: empty]
time 6627ms: Process A completed I/O; added to ready queue [Q: A]
time 6629ms: Process A started using the CPU for 11ms burst [Q: empty]
time 6640ms: Process A completed a CPU burst; 6 bursts to go [Q: empty]
time 6640ms: Process A switching out of CPU; will block on I/O until time 6932ms [Q: empty]
time 6932ms: Process A completed I/O; added to ready queue [Q: A]
time 6934ms: Process A started using the CPU for 82ms burst [Q: empty]
time 6960ms: Process H completed I/O; added to ready queue [Q: H]
time 6999ms: Process F completed I/O; added to ready queue [Q: H F]
time 7016ms: Process A completed a CPU burst; 5 bursts to go [Q: H F]
time 7016ms: Process A switching out of CPU; will block on I/O until time 8768ms [Q: H F]
time 7020ms: Process H started using the CPU for 252ms burst [Q: F]
time 7272ms: Process H completed a CPU burst; 79 bursts to go [Q: F]
time 7272ms: Process H switching out of CPU; will block on I/O until time 7624ms [Q: F]
time 7276ms: Process F started using the CPU for 96ms burst [Q: empty]
time 7372ms: Process F completed a CPU burst; 57 bursts to go [Q: empty]
time 7372ms: Process F switching out of CPU; will block on I/O until time 7774ms [Q: empty]
time 7444ms: Process B completed I/O; added to ready queue [Q: B]
time 7446ms: Process B started using the CPU for 61ms burst [Q: empty]
time 7465ms: Process D completed I/O; added to ready queue [Q: D]
time 7474ms: Process C completed I/O; added to ready queue [Q: D C]
time 7507ms: Process B completed a CPU burst; 51 bursts to go [Q: D C]
time 7507ms: Process B switching out of CPU; will block on I/O until time 7619ms [Q: D C]
time 7511ms: Process D started using the CPU for 57ms burst [Q: C]
time 7511ms: Process G completed I/O; added to ready queue [Q: C G]
time 7568ms: Process D completed a CPU burst; 73 bursts to go [Q: C G]
time 7568ms: Process D switching out of CPU; will block on I/O until time 9180ms [Q: C G]
time 7572ms: Process C started using the CPU for 348ms burst [Q: G]
time 7619ms: Process B completed I/O; added to ready queue [Q: G B]
time 7624ms: Process H completed I/O; added to ready queue [Q: G B H]
time 7774ms: Process F completed I/O; added to ready queue [Q: G B H F]
time 7788ms: Process E completed I/O; added to ready queue [Q: G B H F E]
time 7920ms: Process C completed a CPU burst; 30 bursts to go [Q: G B H F E]
time 7920ms: Process C switching out of CPU; will block on I/O until time 8502ms [Q: G B H F E]
time 7924ms: Process G started using the CPU for 10ms burst [Q: B H F E]
time 7934ms: Process G completed a CPU burst; 38 bursts to go [Q: B H F E]
time 7934ms: Process G switching out of CPU; will block on I/O until time 8016ms [Q: B H F E]
time 7938ms: Process B started using the CPU for 73ms burst [Q: H F E]
time 8011ms: Process B completed a CPU burst; 50 bursts to go [Q: H F E]
time 8011ms: Process B switching out of CPU; will block on I/O until time 8253ms [Q: H F E]
time 8015ms: Process H started using the CPU for 15ms burst [Q: F E]
time 8016ms: Process G completed I/O; added to ready queue [Q: F E G]
time 8030ms: Process H completed a CPU burst; 78 bursts to go [Q: F E G]
time 8030ms: Process H switching out of CPU; will block on I/O until time 8112ms [Q: F E G]
time 8034ms: Process F started using the CPU for 63ms burst [Q: E G]
time 8097ms: Process F completed a CPU burst; 56 bursts to go [Q: E G]
time 8097ms: Process F switching out of CPU; will block on I/O until time 8359ms [Q: E G]
time 8101ms: Process E started using the CPU for 9ms burst [Q: G]
time 8110ms: Process E completed a CPU burst; 71 bursts to go [Q: G]
time 8110ms: Process E switching out of CPU; will block on I/O until time 11222ms [Q: G]
time 8112ms: Process H completed I/O; added to ready queue [Q: G H]
time 8114ms: Process G started using the CPU for 92ms burst [Q: H]
time 8206ms: Process G completed a CPU burst; 37 bursts to go [Q: H]
time 8206ms: Process G switching out of CPU; will block on I/O until time 9728ms [Q: H]
time 8210ms: Process H started using the CPU for 25ms burst [Q: empty]
time 8235ms: Process H completed a CPU burst; 77 bursts to go [Q: empty]
time 8235ms: Process H switching out of CPU; will block on I/O until time 8247ms [Q: empty]
time 8247ms: Process H completed I/O; added to ready queue [Q: H]
time 8249ms: Process H started using the CPU for 384ms burst [Q: empty]
time 8253ms: Process B completed I/O; added to ready queue [Q: B]
time 8359ms: Process F completed I/O; added to ready queue [Q: B F]
time 8502ms: Process C completed I/O; added to ready queue [Q: B F C]
time 8633ms: Process H completed a CPU burst; 76 bursts to go [Q: B F C]
time 8633ms: Process H switching out of CPU; will block on I/O until time 8825ms [Q: B F C]
time 8637ms: Process B started using the CPU for 56ms burst [Q: F C]
time 8693ms: Process B completed a CPU burst; 49 bursts to go [Q: F C]
time 8693ms: Process B switching out of CPU; will block on I/O until time 9655ms [Q: F C]
time 8697ms: Process F started using the CPU for 66ms burst [Q: C]
time 8763ms: Process F completed a CPU burst; 55 bursts to go [Q: C]
time 8763ms: Process F switching out of CPU; will block on I/O until time 9545ms [Q: C]
time 8767ms: Process C started using the CPU for 58ms burst [Q: empty]
time 8768ms: Process A completed I/O; added to ready queue [Q: A]
time 8825ms: Process C completed a CPU burst; 29 bursts to go [Q: A]
time 8825ms: Process C switching out of CPU; will block on I/O until time 10077ms [Q: A]
time 8825ms: Process H completed I/O; added to ready queue [Q: A H]
time 8829ms: Process A started using the CPU for 49ms burst [Q: H]
time 8878ms: Process A completed a CPU burst; 4 bursts to go [Q: H]
time 8878ms: Process A switching out of CPU; will block on I/O until time 12460ms [Q: H]
time 8882ms: Process H started using the CPU for 24ms burst [Q: empty]
time 8906ms: Process H completed a CPU burst; 75 bursts to go [Q: empty]
time 8906ms: Process H switching out of CPU; will block on I/O until time 8948ms [Q: empty]
time 8948ms: Process H completed I/O; added to ready queue [Q: H]
time 8950ms: Process H started using the CPU for 63ms burst [Q: empty]
time 9013ms: Process H completed a CPU burst; 74 bursts to go [Q: empty]
time 9013ms: Process H switching out of CPU; will block on I/O until time 9425ms [Q: empty]
time 9180ms: Process D completed I/O; added to ready queue [Q: D]
time 9182ms: Process D started using the CPU for 65ms burst [Q: empty]
time 9247ms: Process D completed a CPU burst; 72 bursts to go [Q: empty]
time 9247ms: Process D switching out of CPU; will block on I/O until time 11969ms [Q: empty]
time 9425ms: Process H completed I/O; added to ready queue [Q: H]
time 9427ms: Process H started using the CPU for 44ms burst [Q: empty]
time 9471ms: Process H completed a CPU burst; 73 bursts to go [Q: empty]
time 9471ms: Process H switching out of CPU; will block on I/O until time 10713ms [Q: empty]
time 9545ms: Process F completed I/O; added to ready queue [Q: F]
time 9547ms: Process F started using the CPU for 317ms burst [Q: empty]
time 9655ms: Process B completed I/O; added to ready queue [Q: B]
time 9728ms: Process G completed I/O; added to ready queue [Q: B G]
time 9864ms: Process F completed a CPU burst; 54 bursts to go [Q: B G]
time 9864ms: Process F switching out of CPU; will block on I/O until time 10006ms [Q: B G]
time 9868ms: Process B started using the CPU for 32ms burst [Q: G]
time 9900ms: Process B completed a CPU burst; 48 bursts to go [Q: G]
time 9900ms: Process B switching out of CPU; will block on I/O until time 11512ms [Q: G]
time 9904ms: Process G started using the CPU for 46ms burst [Q: empty]
time 9950ms: Process G completed a CPU burst; 36 bursts to go [Q: empty]
time 9950ms: Process G switching out of CPU; will block on I/O until time 10852ms [Q: empty]
time 10006ms: Process F completed I/O; added to ready queue [Q: F]
time 10008ms: Process F started using the CPU for 5ms burst [Q: empty]
time 10013ms: Process F completed a CPU burst; 53 bursts to go [Q: empty]
time 10013ms: Process F switching out of CPU; will block on I/O until time 10315ms [Q: empty]
time 10077ms: Process C completed I/O; added to ready queue [Q: C]
time 10079ms: Process C started using the CPU for 88ms burst [Q: empty]
time 10167ms: Process C completed a CPU burst; 28 bursts to go [Q: empty]
time 10167ms: Process C switching out of CPU; will block on I/O until time 10519ms [Q: empty]
time 10315ms: Process F completed I/O; added to ready queue [Q: F]
time 10317ms: Process F started using the CPU for 3ms burst [Q: empty]
time 10320ms: Process F completed a CPU burst; 52 bursts to go [Q: empty]
time 10320ms: Process F switching out of CPU; will block on I/O until time 10452ms [Q: empty]
time 10452ms: Process F completed I/O; added to ready queue [Q: F]
time 10454ms: Process F started using the CPU for 234ms burst [Q: empty]
time 10519ms: Process C completed I/O; added to ready queue [Q: C]
time 10688ms: Process F completed a CPU burst; 51 bursts to go [Q: C]
time 10688ms: Process F switching out of CPU; will block on I/O until time 12050ms [Q: C]
time 10692ms: Process C started using the CPU for 43ms burst [Q: empty]
time 10713ms: Process H completed I/O; added to ready queue [Q: H]
time 10735ms: Process C completed a CPU burst; 27 bursts to go [Q: H]
time 10735ms: Process C switching out of CPU; will block on I/O until time 11517ms [Q: H]
time 10739ms: Process H started using the CPU for 138ms burst [Q: empty]
time 10852ms: Process G completed I/O; added to ready queue [Q: G]
time 10877ms: Process H completed a CPU burst; 72 bursts to go [Q: G]
time 10877ms: Process H switching out of CPU; will block on I/O until time 11349ms [Q: G]
time 10881ms: Process G started using the CPU for 36ms burst [Q: empty]
time 10917ms: Process G completed a CPU burst; 35 bursts to go [Q: empty]
time 10917ms: Process G switching out of CPU; will block on I/O until time 10969ms [Q: empty]
time 10969ms: Process G completed I/O; added to ready queue [Q: G]
time 10971ms: Process G started using the CPU for 96ms burst [Q: empty]
time 11067ms: Process G completed a CPU burst; 34 bursts to go [Q: empty]
time 11067ms: Process G switching out of CPU; will block on I/O until time 11229ms [Q: empty]
time 11222ms: Process E completed I/O; added to ready queue [Q: E]
time 11224ms: Process E started using the CPU for 47ms burst [Q: empty]
time 11229ms: Process G completed I/O; added to ready queue [Q: G]
time 11271ms: Process E completed a CPU burst; 70 bursts to go [Q: G]
time 11271ms: Process E switching out of CPU; will block on I/O until time 11483ms [Q: G]
time 11275ms: Process G started using the CPU for 337ms burst [Q: empty]
time 11349ms: Process H completed I/O; added to ready queue [Q: H]
time 11483ms: Process E completed I/O; added to ready queue [Q: H E]
time 11512ms: Process B completed I/O; added to ready queue [Q: H E B]
time 11517ms: Process C completed I/O; added to ready queue [Q: H E B C]
time 11612ms: Process G completed a CPU burst; 33 bursts to go [Q: H E B C]
time 11612ms: Process G switching out of CPU; will block on I/O until time 11994ms [Q: H E B C]
time 11616ms: Process H started using the CPU for 102ms burst [Q: E B C]
time 11718ms: Process H completed a CPU burst; 71 bursts to go [Q: E B C]
time 11718ms: Process H switching out of CPU; will block on I/O until time 11980ms [Q: E B C]
time 11722ms: Process E started using the CPU for 13ms burst [Q: B C]
time 11735ms: Process E completed a CPU burst; 69 bursts to go [Q: B C]
time 11735ms: Process E switching out of CPU; will block on I/O until time 12467ms [Q: B C]
time 11739ms: Process B started using the CPU for 79ms burst [Q: C]
time 11818ms: Process B completed a CPU burst; 47 bursts to go [Q: C]
time 11818ms: Process B switching out of CPU; will block on I/O until time 11860ms [Q: C]
time 11822ms: Process C started using the CPU for 115ms burst [Q: empty]
time 11860ms: Process B completed I/O; added to ready queue [Q: B]
time 11937ms: Process C completed a CPU burst; 26 bursts to go [Q: B]
time 11937ms: Process C switching out of CPU; will block on I/O until time 12309ms [Q: B]
time 11941ms: Process B started using the CPU for 70ms burst [Q: empty]
time 11969ms: Process D completed I/O; added to ready queue [Q: D]
time 11980ms: Process H completed I/O; added to ready queue [Q: D H]
time 11994ms: Process G completed I/O; added to ready queue [Q: D H G]
time 12011ms: Process B completed a CPU burst; 46 bursts to go [Q: D H G]
time 12011ms: Process B switching out of CPU; will block on I/O until time 14083ms [Q: D H G]
time 12015ms: Process D started using the CPU for 221ms burst [Q: H G]
time 12050ms: Process F completed I/O; added to ready queue [Q: H G F]
time 12236ms: Process D completed a CPU burst; 71 bursts to go [Q: H G F]
time 12236ms: Process D switching out of CPU; will block on I/O until time 13218ms [Q: H G F]
time 12240ms: Process H started using the CPU for 10ms burst [Q: G F]
time 12250ms: Process H completed a CPU burst; 70 bursts to go [Q: G F]
time 12250ms: Process H switching out of CPU; will block on I/O until time 12672ms [Q: G F]
time 12254ms: Process G started using the CPU for 9ms burst [Q: F]
time 12263ms: Process G completed a CPU burst; 32 bursts to go [Q: F]
time 12263ms: Process G switching out of CPU; will block on I/O until time 13695ms [Q: F]
time 12267ms: Process F started using the CPU for 209ms burst [Q: empty]
time 12309ms: Process C completed I/O; added to ready queue [Q: C]
time 12460ms: Process A completed I/O; added to ready queue [Q: C A]
time 12467ms: Process E completed I/O; added to ready queue [Q: C A E]
time 12476ms: Process F completed a CPU burst; 50 bursts to go [Q: C A E]
time 12476ms: Process F switching out of CPU; will block on I/O until time 13818ms [Q: C A E]
time 12480ms: Process C started using the CPU for 145ms burst [Q: A E]
time 12625ms: Process C completed a CPU burst; 25 bursts to go [Q: A E]
time 12625ms: Process C switching out of CPU; will block on I/O until time 13137ms [Q: A E]
time 12629ms: Process A started using the CPU for 117ms burst [Q: E]
time 12672ms: Process H completed I/O; added to ready queue [Q: E H]
time 12746ms: Process A completed a CPU burst; 3 bursts to go [Q: E H]
time 12746ms: Process A switching out of CPU; will block on I/O until time 12908ms [Q: E H]
time 12750ms: Process E started using the CPU for 6ms burst [Q: H]
time 12756ms: Process E completed a CPU burst; 68 bursts to go [Q: H]
time 12756ms: Process E switching out of CPU; will block on I/O until time 14538ms [Q: H]
time 12760ms: Process H started using the CPU for 43ms burst [Q: empty]
time 12803ms: Process H completed a CPU burst; 69 bursts to go [Q: empty]
time 12803ms: Process H switching out of CPU; will block on I/O until time 19305ms [Q: empty]
time 12908ms: Process A completed I/O; added to ready queue [Q: A]
time 12910ms: Process A started using the CPU for 73ms burst [Q: empty]
time 12983ms: Process A completed a CPU burst; 2 bursts to go [Q: empty]
time 12983ms: Process A switching out of CPU; will block on I/O until time 14585ms [Q: empty]
time 13137ms: Process C completed I/O; added to ready queue [Q: C]
time 13139ms: Process C started using the CPU for 62ms burst [Q: empty]
time 13201ms: Process C completed a CPU burst; 24 bursts to go [Q: empty]
time 13201ms: Process C switching out of CPU; will block on I/O until time 13773ms [Q: empty]
time 13218ms: Process D completed I/O; added to ready queue [Q: D]
time 13220ms: Process D started using the CPU for 69ms burst [Q: empty]
time 13289ms: Process D completed a CPU burst; 70 bursts to go [Q: empty]
time 13289ms: Process D switching out of CPU; will block on I/O until time 14881ms [Q: empty]
time 13695ms: Process G completed I/O; added to ready queue [Q: G]
time 13697ms: Process G started using the CPU for 41ms burst [Q: empty]
time 13738ms: Process G completed a CPU burst; 31 bursts to go [Q: empty]
time 13738ms: Process G switching out of CPU; will block on I/O until time 14730ms [Q: empty]
time 13773ms: Process C completed I/O; added to ready queue [Q: C]
time 13775ms: Process C started using the CPU for 24ms burst [Q: empty]
time 13799ms: Process C completed a CPU burst; 23 bursts to go [Q: empty]
time 13799ms: Process C switching out of CPU; will block on I/O until time 13901ms [Q: empty]
time 13818ms: Process F completed I/O; added to ready queue [Q: F]
time 13820ms: Process F started using the CPU for 66ms burst [Q: empty]
time 13886ms: Process F completed a CPU burst; 49 bursts to go [Q: empty]
time 13886ms: Process F switching out of CPU; will block on I/O until time 14768ms [Q: empty]
time 13901ms: Process C completed I/O; added to ready queue [Q: C]
time 13903ms: Process C started using the CPU for 170ms burst [Q: empty]
time 14073ms: Process C completed a CPU burst; 22 bursts to go [Q: empty]
time 14073ms: Process C switching out of CPU; will block on I/O until time 14195ms [Q: empty]
time 14083ms: Process B completed I/O; added to ready queue [Q: B]
time 14085ms: Process B started using the CPU for 103ms burst [Q: empty]
time 14188ms: Process B completed a CPU burst; 45 bursts to go [Q: empty]
time 14188ms: Process B switching out of CPU; will block on I/O until time 15940ms [Q: empty]
time 14195ms: Process C completed I/O; added to ready queue [Q: C]
time 14197ms: Process C started using the CPU for 5ms burst [Q: empty]
time 14202ms: Process C completed a CPU burst; 21 bursts to go [Q: empty]
time 14202ms: Process C switching out of CPU; will block on I/O until time 16434ms [Q: empty]
time 14538ms: Process E completed I/O; added to ready queue [Q: E]
time 14540ms: Process E started using the CPU for 73ms burst [Q: empty]
time 14585ms: Process A completed I/O; added to ready queue [Q: A]
time 14613ms: Process E completed a CPU burst; 67 bursts to go [Q: A]
time 14613ms: Process E switching out of CPU; will block on I/O until time 14625ms [Q: A]
time 14617ms: Process A started using the CPU for 117ms burst [Q: empty]
time 14625ms: Process E completed I/O; added to ready queue [Q: E]
time 14730ms: Process G completed I/O; added to ready queue [Q: E G]
time 14734ms: Process A completed a CPU burst; 1 burst to go [Q: E G]
time 14734ms: Process A switching out of CPU; will block on I/O until time 15806ms [Q: E G]
time 14738ms: Process E started using the CPU for 26ms burst [Q: G]
time 14764ms: Process E completed a CPU burst; 66 bursts to go [Q: G]
time 14764ms: Process E switching out of CPU; will block on I/O until time 14856ms [Q: G]
time 14768ms: Process G started using the CPU for 22ms burst [Q: empty]
time 14768ms: Process F completed I/O; added to ready queue [Q: F]
time 14790ms: Process G completed a CPU burst; 30 bursts to go [Q: F]
time 14790ms: Process G switching out of CPU; will block on I/O until time 15342ms [Q: F]
time 14794ms: Process F started using the CPU for 129ms burst [Q: empty]
time 14856ms: Process E completed I/O; added to ready queue [Q: E]
time 14881ms: Process D completed I/O; added to ready queue [Q: E D]
time 14923ms: Process F completed a CPU burst; 48 bursts to go [Q: E D]
time 14923ms: Process F switching out of CPU; will block on I/O until time 17235ms [Q: E D]
time 14927ms: Process E started using the CPU for 204ms burst [Q: D]
time 15131ms: Process E completed a CPU burst; 65 bursts to go [Q: D]
time 15131ms: Process E switching out of CPU; will block on I/O until time 15443ms [Q: D]
time 15135ms: Process D started using the CPU for 11ms burst [Q: empty]
time 15146ms: Process D completed a CPU burst; 69 bursts to go [Q: empty]
time 15146ms: Process D switching out of CPU; will block on I/O until time 15768ms [Q: empty]
time 15342ms: Process G completed I/O; added to ready queue [Q: G]
time 15344ms: Process G started using the CPU for 111ms burst [Q: empty]
time 15443ms: Process E completed I/O; added to ready queue [Q: E]
time 15455ms: Process G completed a CPU burst; 29 bursts to go [Q: E]
time 15455ms: Process G switching out of CPU; will block on I/O until time 16387ms [Q: E]
time 15459ms: Process E started using the CPU for 4ms burst [Q: empty]
time 15463ms: Process E completed a CPU burst; 64 bursts to go [Q: empty]
time 15463ms: Process E switching out of CPU; will block on I/O until time 16825ms [Q: empty]
time 15768ms: Process D completed I/O; added to ready queue [Q: D]
time 15770ms: Process D started using the CPU for 2ms burst [Q: empty]
time 15772ms: Process D completed a CPU burst; 68 bursts to go [Q: empty]
time 15772ms: Process D switching out of CPU; will block on I/O until time 16084ms [Q: empty]
time 15806ms: Process A completed I/O; added to ready queue [Q: A]
time 15808ms: Process A started using the CPU for 69ms burst [Q: empty]
time 15877ms: Process A terminated [Q: empty]
time 15940ms: Process B completed I/O; added to ready queue [Q: B]
time 15942ms: Process B started using the CPU for 148ms burst [Q: empty]
time 16084ms: Process D completed I/O; added to ready queue [Q: D]
time 16090ms: Process B completed a CPU burst; 44 bursts to go [Q: D]
time 16090ms: Process B switching out of CPU; will block on I/O until time 16852ms [Q: D]
time 16094ms: Process D started using the CPU for 34ms burst [Q: empty]
time 16128ms: Process D completed a CPU burst; 67 bursts to go [Q: empty]
time 16128ms: Process D switching out of CPU; will block on I/O until time 18840ms [Q: empty]
time 16387ms: Process G completed I/O; added to ready queue [Q: G]
time 16389ms: Process G started using the CPU for 58ms burst [Q: empty]
time 16434ms: Process C completed I/O; added to ready queue [Q: C]
time 16447ms: Process G completed a CPU burst; 28 bursts to go [Q: C]
time 16447ms: Process G switching out of CPU; will block on I/O until time 17289ms [Q: C]
time 16451ms: Process C started using the CPU for 59ms burst [Q: empty]
time 16510ms: Process C completed a CPU burst; 20 bursts to go [Q: empty]
time 16510ms: Process C switching out of CPU; will block on I/O until time 18042ms [Q: empty]
time 16825ms: Process E completed I/O; added to ready queue [Q: E]
time 16827ms: Process E started using the CPU for 63ms burst [Q: empty]
time 16852ms: Process B completed I/O; added to ready queue [Q: B]
time 16890ms: Process E completed a CPU burst; 63 bursts to go [Q: B]
time 16890ms: Process E switching out of CPU; will block on I/O until time 17332ms [Q: B]
time 16894ms: Process B started using the CPU for 63ms burst [Q: empty]
time 16957ms: Process B completed a CPU burst; 43 bursts to go [Q: empty]
time 16957ms: Process B switching out of CPU; will block on I/O until time 17049ms [Q: empty]
time 17049ms: Process B completed I/O; added to ready queue [Q: B]
time 17051ms: Process B started using the CPU for 8ms burst [Q: empty]
time 17059ms: Process B completed a CPU burst; 42 bursts to go [Q: empty]
time 17059ms: Process B switching out of CPU; will block on I/O until time 18151ms [Q: empty]
time 17235ms: Process F completed I/O; added to ready queue [Q: F]
time 17237ms: Process F started using the CPU for 31ms burst [Q: empty]
time 17268ms: Process F completed a CPU burst; 47 bursts to go [Q: empty]
time 17268ms: Process F switching out of CPU; will block on I/O until time 18920ms [Q: empty]
time 17289ms: Process G completed I/O; added to ready queue [Q: G]
time 17291ms: Process G started using the CPU for 60ms burst [Q: empty]
time 17332ms: Process E completed I/O; added to ready queue [Q: E]
time 17351ms: Process G completed a CPU burst; 27 bursts to go [Q: E]
time 17351ms: Process G switching out of CPU; will block on I/O until time 18313ms [Q: E]
time 17355ms: Process E started using the CPU for 261ms burst [Q: empty]
time 17616ms: Process E completed a CPU burst; 62 bursts to go [Q: empty]
time 17616ms: Process E switching out of CPU; will block on I/O until time 18398ms [Q: empty]
time 18042ms: Process C completed I/O; added to ready queue [Q: C]
time 18044ms: Process C started using the CPU for 13ms burst [Q: empty]
time 18057ms: Process C completed a CPU burst; 19 bursts to go [Q: empty]
time 18057ms: Process C switching out of CPU; will block on I/O until time 18219ms [Q: empty]
time 18151ms: Process B completed I/O; added to ready queue [Q: B]
time 18153ms: Process B started using the CPU for 95ms burst [Q: empty]
time 18219ms: Process C completed I/O; added to ready queue [Q: C]
time 18248ms: Process B completed a CPU burst; 41 bursts to go [Q: C]
time 18248ms: Process B switching out of CPU; will block on I/O until time 19590ms [Q: C]
time 18252ms: Process C started using the CPU for 2ms burst [Q: empty]
time 18254ms: Process C completed a CPU burst; 18 bursts to go [Q: empty]
time 18254ms: Process C switching out of CPU; will block on I/O until time 19066ms [Q: empty]
time 18313ms: Process G completed I/O; added to ready queue [Q: G]
time 18315ms: Process G started using the CPU for 270ms burst [Q: empty]
time 18398ms: Process E completed I/O; added to ready queue [Q: E]
time 18585ms: Process G completed a CPU burst; 26 bursts to go [Q: E]
time 18585ms: Process G switching out of CPU; will block on I/O until time 18907ms [Q: E]
time 18589ms: Process E started using the CPU for 76ms burst [Q: empty]
time 18665ms: Process E completed a CPU burst; 61 bursts to go [Q: empty]
time 18665ms: Process E switching out of CPU; will block on I/O until time 18997ms [Q: empty]
time 18840ms: Process D completed I/O; added to ready queue [Q: D]
time 18842ms: Process D started using the CPU for 225ms burst [Q: empty]
time 18907ms: Process G completed I/O; added to ready queue [Q: G]
time 18920ms: Process F completed I/O; added to ready queue [Q: G F]
time 18997ms: Process E completed I/O; added to ready queue [Q: G F E]
time 19066ms: Process C completed I/O; added to ready queue [Q: G F E C]
time 19067ms: Process D completed a CPU burst; 66 bursts to go [Q: G F E C]
time 19067ms: Process D switching out of CPU; will block on I/O until time 20439ms [Q: G F E C]
time 19071ms: Process G started using the CPU for 81ms burst [Q: F E C]
time 19152ms: Process G completed a CPU burst; 25 bursts to go [Q: F E C]
time 19152ms: Process G switching out of CPU; will block on I/O until time 19744ms [Q: F E C]
time 19156ms: Process F started using the CPU for 119ms burst [Q: E C]
time 19275ms: Process F completed a CPU burst; 46 bursts to go [Q: E C]
time 19275ms: Process F switching out of CPU; will block on I/O until time 19457ms [Q: E C]
time 19279ms: Process E started using the CPU for 19ms burst [Q: C]
time 19298ms: Process E completed a CPU burst; 60 bursts to go [Q: C]
time 19298ms: Process E switching out of CPU; will block on I/O until time 20710ms [Q: C]
time 19302ms: Process C started using the CPU for 67ms burst [Q: empty]
time 19305ms: Process H completed I/O; added to ready queue [Q: H]
time 19369ms: Process C completed a CPU burst; 17 bursts to go [Q: H]
time 19369ms: Process C switching out of CPU; will block on I/O until time 19691ms [Q: H]
time 19373ms: Process H started using the CPU for 33ms burst [Q: empty]
time 19406ms: Process H completed a CPU burst; 68 bursts to go [Q: empty]
time 19406ms: Process H switching out of CPU; will block on I/O until time 19518ms [Q: empty]
time 19457ms: Process F completed I/O; added to ready queue [Q: F]
time 19459ms: Process F started using the CPU for 53ms burst [Q: empty]
time 19512ms: Process F completed a CPU burst; 45 bursts to go [Q: empty]
time 19512ms: Process F switching out of CPU; will block on I/O until time 20084ms [Q: empty]
time 19518ms: Process H completed I/O; added to ready queue [Q: H]
time 19520ms: Process H started using the CPU for 208ms burst [Q: empty]
time 19590ms: Process B completed I/O; added to ready queue [Q: B]
time 19691ms: Process C completed I/O; added to ready queue [Q: B C]
time 19728ms: Process H completed a CPU burst; 67 bursts to go [Q: B C]
time 19728ms: Process H switching out of CPU; will block on I/O until time 22200ms [Q: B C]
time 19732ms: Process B started using the CPU for 45ms burst [Q: C]
time 19744ms: Process G completed I/O; added to ready queue [Q: C G]
time 19777ms: Process B completed a CPU burst; 40 bursts to go [Q: C G]
time 19777ms: Process B switching out of CPU; will block on I/O until time 20489ms [Q: C G]
time 19781ms: Process C started using the CPU for 122ms burst [Q: G]
time 19903ms: Process C completed a CPU burst; 16 bursts to go [Q: G]
time 19903ms: Process C switching out of CPU; will block on I/O until time 20205ms [Q: G]
time 19907ms: Process G started using the CPU for 15ms burst [Q: empty]
time 19922ms: Process G completed a CPU burst; 24 bursts to go [Q: empty]
time 19922ms: Process G switching out of CPU; will block on I/O until time 22474ms [Q: empty]
time 20084ms: Process F completed I/O; added to ready queue [Q: F]
time 20086ms: Process F started using the CPU for 202ms burst [Q: empty]
time 20205ms: Process C completed I/O; added to ready queue [Q: C]
time 20288ms: Process F completed a CPU burst; 44 bursts to go [Q: C]
time 20288ms: Process F switching out of CPU; will block on I/O until time 20400ms [Q: C]
time 20292ms: Process C started using the CPU for 122ms burst [Q: empty]
time 20400ms: Process F completed I/O; added to ready queue [Q: F]
time 20414ms: Process C completed a CPU burst; 15 bursts to go [Q: F]
time 20414ms: Process C switching out of CPU; will block on I/O until time 20676ms [Q: F]
time 20418ms: Process F started using the CPU for 37ms burst [Q: empty]
time 20439ms: Process D completed I/O; added to ready queue [Q: D]
time 20455ms: Process F completed a CPU burst; 43 bursts to go [Q: D]
time 20455ms: Process F switching out of CPU; will block on I/O until time 21527ms [Q: D]
time 20459ms: Process D started using the CPU for 240ms burst [Q: empty]
time 20489ms: Process B completed I/O; added to ready queue [Q: B]
time 20676ms: Process C completed I/O; added to ready queue [Q: B C]
time 20699ms: Process D completed a CPU burst; 65 bursts to go [Q: B C]
time 20699ms: Process D switching out of CPU; will block on I/O until time 22751ms [Q: B C]
time 20703ms: Process B started using the CPU for 142ms burst [Q: C]
time 20710ms: Process E completed I/O; added to ready queue [Q: C E]
time 20845ms: Process B completed a CPU burst; 39 bursts to go [Q: C E]
time 20845ms: Process B switching out of CPU; will block on I/O until time 20857ms [Q: C E]
time 20849ms: Process C started using the CPU for 311ms burst [Q: E]
time 20857ms: Process B completed I/O; added to ready queue [Q: E B]
time 21160ms: Process C completed a CPU burst; 14 bursts to go [Q: E B]
time 21160ms: Process C switching out of CPU; will block on I/O until time 25062ms [Q: E B]
time 21164ms: Process E started using the CPU for 35ms burst [Q: B]
time 21199ms: Process E completed a CPU burst; 59 bursts to go [Q: B]
time 21199ms: Process E switching out of CPU; will block on I/O until time 22461ms [Q: B]
time 21203ms: Process B started using the CPU for 56ms burst [Q: empty]
time 21259ms: Process B completed a CPU burst; 38 bursts to go [Q: empty]
time 21259ms: Process B switching out of CPU; will block on I/O until time 21601ms [Q: empty]
time 21527ms: Process F completed I/O; added to ready queue [Q: F]
time 21529ms: Process F started using the CPU for 49ms burst [Q: empty]
time 21578ms: Process F completed a CPU burst; 42 bursts to go [Q: empty]
time 21578ms: Process F switching out of CPU; will block on I/O until time 22500ms [Q: empty]
time 21601ms: Process B completed I/O; added to ready queue [Q: B]
time 21603ms: Process B started using the CPU for 6ms burst [Q: empty]
time 21609ms: Process B completed a CPU burst; 37 bursts to go [Q: empty]
time 21609ms: Process B switching out of CPU; will block on I/O until time 26261ms [Q: empty]
time 22200ms: Process H completed I/O; added to ready queue [Q: H]
time 22202ms: Process H started using the CPU for 153ms burst [Q: empty]
time 22355ms: Process H completed a CPU burst; 66 bursts to go [Q: empty]
time 22355ms: Process H switching out of CPU; will block on I/O until time 22757ms [Q: empty]
time 22461ms: Process E completed I/O; added to ready queue [Q: E]
time 22463ms: Process E started using the CPU for 85ms burst [Q: empty]
time 22474ms: Process G completed I/O; added to ready queue [Q: G]
time 22500ms: Process F completed I/O; added to ready queue [Q: G F]
time 22548ms: Process E completed a CPU burst; 58 bursts to go [Q: G F]
time 22548ms: Process E switching out of CPU; will block on I/O until time 23350ms [Q: G F]
time 22552ms: Process G started using the CPU for 191ms burst [Q: F]
time 22743ms: Process G completed a CPU burst; 23 bursts to go [Q: F]
time 22743ms: Process G switching out of CPU; will block on I/O until time 25145ms [Q: F]
time 22747ms: Process F started using the CPU for 198ms burst [Q: empty]
time 22751ms: Process D completed I/O; added to ready queue [Q: D]
time 22757ms: Process H completed I/O; added to ready queue [Q: D H]
time 22945ms: Process F completed a CPU burst; 41 bursts to go [Q: D H]
time 22945ms: Process F switching out of CPU; will block on I/O until time 23397ms [Q: D H]
time 22949ms: Process D started using the CPU for 33ms burst [Q: H]
time 22982ms: Process D completed a CPU burst; 64 bursts to go [Q: H]
time 22982ms: Process D switching out of CPU; will block on I/O until time 23274ms [Q: H]
time 22986ms: Process H started using the CPU for 306ms burst [Q: empty]
time 23274ms: Process D completed I/O; added to ready queue [Q: D]
time 23292ms: Process H completed a CPU burst; 65 bursts to go [Q: D]
time 23292ms: Process H switching out of CPU; will block on I/O until time 23374ms [Q: D]
time 23296ms: Process D started using the CPU for 110ms burst [Q: empty]
time 23350ms: Process E completed I/O; added to ready queue [Q: E]
time 23374ms: Process H completed I/O; added to ready queue [Q: E H]
time 23397ms: Process F completed I/O; added to ready queue [Q: E H F]
time 23406ms: Process D completed a CPU burst; 63 bursts to go [Q: E H F]
time 23406ms: Process D switching out of CPU; will block on I/O until time 26298ms [Q: E H F]
time 23410ms: Process E started using the CPU for 34ms burst [Q: H F]
time 23444ms: Process E completed a CPU burst; 57 bursts to go [Q: H F]
time 23444ms: Process E switching out of CPU; will block on I/O until time 23666ms [Q: H F]
time 23448ms: Process H started using the CPU for 18ms burst [Q: F]
time 23466ms: Process H completed a CPU burst; 64 bursts to go [Q: F]
time 23466ms: Process H switching out of CPU; will block on I/O until time 23678ms [Q: F]
time 23470ms: Process F started using the CPU for 21ms burst [Q: empty]
time 23491ms: Process F completed a CPU burst; 40 bursts to go [Q: empty]
time 23491ms: Process F switching out of CPU; will block on I/O until time 23863ms [Q: empty]
time 23666ms: Process E completed I/O; added to ready queue [Q: E]
time 23668ms: Process E started using the CPU for 54ms burst [Q: empty]
time 23678ms: Process H completed I/O; added to ready queue [Q: H]
time 23722ms: Process E completed a CPU burst; 56 bursts to go [Q: H]
time 23722ms: Process E switching out of CPU; will block on I/O until time 25794ms [Q: H]
time 23726ms: Process H started using the CPU for 288ms burst [Q: empty]
time 23863ms: Process F completed I/O; added to ready queue [Q: F]
time 24014ms: Process H completed a CPU burst; 63 bursts to go [Q: F]
time 24014ms: Process H switching out of CPU; will block on I/O until time 25686ms [Q: F]
time 24018ms: Process F started using the CPU for 35ms burst [Q: empty]
time 24053ms: Process F completed a CPU burst; 39 bursts to go [Q: empty]
time 24053ms: Process F switching out of CPU; will block on I/O until time 25265ms [Q: empty]
time 25062ms: Process C completed I/O; added to ready queue [Q: C]
time 25064ms: Process C started using the CPU for 37ms burst [Q: empty]
time 25101ms: Process C completed a CPU burst; 13 bursts to go [Q: empty]
time 25101ms: Process C switching out of CPU; will block on I/O until time 26803ms [Q: empty]
time 25145ms: Process G completed I/O; added to ready queue [Q: G]
time 25147ms: Process G started using the CPU for 21ms burst [Q: empty]
time 25168ms: Process G completed a CPU burst; 22 bursts to go [Q: empty]
time 25168ms: Process G switching out of CPU; will block on I/O until time 25320ms [Q: empty]
time 25265ms: Process F completed I/O; added to ready queue [Q: F]
time 25267ms: Process F started using the CPU for 21ms burst [Q: empty]
time 25288ms: Process F completed a CPU burst; 38 bursts to go [Q: empty]
time 25288ms: Process F switching out of CPU; will block on I/O until time 25470ms [Q: empty]
time 25320ms: Process G completed I/O; added to ready queue [Q: G]
time 25322ms: Process G started using the CPU for 45ms burst [Q: empty]
time 25367ms: Process G completed a CPU burst; 21 bursts to go [Q: empty]
time 25367ms: Process G switching out of CPU; will block on I/O until time 26009ms [Q: empty]
time 25470ms: Process F completed I/O; added to ready queue [Q: F]
time 25472ms: Process F started using the CPU for 87ms burst [Q: empty]
time 25559ms: Process F completed a CPU burst; 37 bursts to go [Q: empty]
time 25559ms: Process F switching out of CPU; will block on I/O until time 25791ms [Q: empty]
time 25686ms: Process H completed I/O; added to ready queue [Q: H]
time 25688ms: Process H started using the CPU for 14ms burst [Q: empty]
time 25702ms: Process H completed a CPU burst; 62 bursts to go [Q: empty]
time 25702ms: Process H switching out of CPU; will block on I/O until time 26364ms [Q: empty]
time 25791ms: Process F completed I/O; added to ready queue [Q: F]
time 25793ms: Process F started using the CPU for 10ms burst [Q: empty]
time 25794ms: Process E completed I/O; added to ready queue [Q: E]
time 25803ms: Process F completed a CPU burst; 36 bursts to go [Q: E]
time 25803ms: Process F switching out of CPU; will block on I/O until time 25815ms [Q: E]
time 25807ms: Process E started using the CPU for 37ms burst [Q: empty]
time 25815ms: Process F completed I/O; added to ready queue [Q: F]
time 25844ms: Process E completed a CPU burst; 55 bursts to go [Q: F]
time 25844ms: Process E switching out of CPU; will block on I/O until time 27146ms [Q: F]
time 25848ms: Process F started using the CPU for 22ms burst [Q: empty]
time 25870ms: Process F completed a CPU burst; 35 bursts to go [Q: empty]
time 25870ms: Process F switching out of CPU; will block on I/O until time 28442ms [Q: empty]
time 26009ms: Process G completed I/O; added to ready queue [Q: G]
time 26011ms: Process G started using the CPU for 4ms burst [Q: empty]
time 26015ms: Process G completed a CPU burst; 20 bursts to go [Q: empty]
time 26015ms: Process G switching out of CPU; will block on I/O until time 27747ms [Q: empty]
time 26261ms: Process B completed I/O; added to ready queue [Q: B]
time 26263ms: Process B started using the CPU for 209ms burst [Q: empty]
time 26298ms: Process D completed I/O; added to ready queue [Q: D]
time 26364ms: Process H completed I/O; added to ready queue [Q: D H]
time 26472ms: Process B completed a CPU burst; 36 bursts to go [Q: D H]
time 26472ms: Process B switching out of CPU; will block on I/O until time 26554ms [Q: D H]
time 26476ms: Process D started using the CPU for 11ms burst [Q: H]
time 26487ms: Process D completed a CPU burst; 62 bursts to go [Q: H]
time 26487ms: Process D switching out of CPU; will block on I/O until time 28009ms [Q: H]
time 26491ms: Process H started using the CPU for 15ms burst [Q: empty]
time 26506ms: Process H completed a CPU burst; 61 bursts to go [Q: empty]
time 26506ms: Process H switching out of CPU; will block on I/O until time 26758ms [Q: empty]
time 26554ms: Process B completed I/O; added to ready queue [Q: B]
time 26556ms: Process B started using the CPU for 211ms burst [Q: empty]
time 26758ms: Process H completed I/O; added to ready queue [Q: H]
time 26767ms: Process B completed a CPU burst; 35 bursts to go [Q: H]
time 26767ms: Process B switching out of CPU; will block on I/O until time 27829ms [Q: H]
time 26771ms: Process H started using the CPU for 295ms burst [Q: empty]
time 26803ms: Process C completed I/O; added to ready queue [Q: C]
time 27066ms: Process H completed a CPU burst; 60 bursts to go [Q: C]
time 27066ms: Process H switching out of CPU; will block on I/O until time 27568ms [Q: C]
time 27070ms: Process C started using the CPU for 81ms burst [Q: empty]
time 27146ms: Process E completed I/O; added to ready queue [Q: E]
time 27151ms: Process C completed a CPU burst; 12 bursts to go [Q: E]
time 27151ms: Process C switching out of CPU; will block on I/O until time 30533ms [Q: E]
time 27155ms: Process E started using the CPU for 265ms burst [Q: empty]
time 27420ms: Process E completed a CPU burst; 54 bursts to go [Q: empty]
time 27420ms: Process E switching out of CPU; will block on I/O until time 27792ms [Q: empty]
time 27568ms: Process H completed I/O; added to ready queue [Q: H]
time 27570ms: Process H started using the CPU for 27ms burst [Q: empty]
time 27597ms: Process H completed a CPU burst; 59 bursts to go [Q: empty]
time 27597ms: Process H switching out of CPU; will block on I/O until time 27649ms [Q: empty]
time 27649ms: Process H completed I/O; added to ready queue [Q: H]
time 27651ms: Process H started using the CPU for 103ms burst [Q: empty]
time 27747ms: Process G completed I/O; added to ready queue [Q: G]
time 27754ms: Process H completed a CPU burst; 58 bursts to go [Q: G]
time 27754ms: Process H switching out of CPU; will block on I/O until time 27906ms [Q: G]
time 27758ms: Process G started using the CPU for 182ms burst [Q: empty]
time 27792ms: Process E completed I/O; added to ready queue [Q: E]
time 27829ms: Process B completed I/O; added to ready queue [Q: E B]
time 27906ms: Process H completed I/O; added to ready queue [Q: E B H]
time 27940ms: Process G completed a CPU burst; 19 bursts to go [Q: E B H]
time 27940ms: Process G switching out of CPU; will block on I/O until time 28162ms [Q: E B H]
time 27944ms: Process E started using the CPU for 230ms burst [Q: B H]
time 28009ms: Process D completed I/O; added to ready queue [Q: B H D]
time 28162ms: Process G completed I/O; added to ready queue [Q: B H D G]
time 28174ms: Process E completed a CPU burst; 53 bursts to go [Q: B H D G]
time 28174ms: Process E switching out of CPU; will block on I/O until time 31706ms [Q: B H D G]
time 28178ms: Process B started using the CPU for 60ms burst [Q: H D G]
time 28238ms: Process B completed a CPU burst; 34 bursts to go [Q: H D G]
time 28238ms: Process B switching out of CPU; will block on I/O until time 29150ms [Q: H D G]
time 28242ms: Process H started using the CPU for 46ms burst [Q: D G]
time 28288ms: Process H completed a CPU burst; 57 bursts to go [Q: D G]
time 28288ms: Process H switching out of CPU; will block on I/O until time 30330ms [Q: D G]
time 28292ms: Process D started using the CPU for 17ms burst [Q: G]
time 28309ms: Process D completed a CPU burst; 61 bursts to go [Q: G]
time 28309ms: Process D switching out of CPU; will block on I/O until time 28731ms [Q: G]
time 28313ms: Process G started using the CPU for 71ms burst [Q: empty]
time 28384ms: Process G completed a CPU burst; 18 bursts to go [Q: empty]
time 28384ms: Process G switching out of CPU; will block on I/O until time 28456ms [Q: empty]
time 28442ms: Process F completed I/O; added to ready queue [Q: F]
time 28444ms: Process F started using the CPU for 194ms burst [Q: empty]
time 28456ms: Process G completed I/O; added to ready queue [Q: G]
time 28638ms: Process F completed a CPU burst; 34 bursts to go [Q: G]
time 28638ms: Process F switching out of CPU; will block on I/O until time 28900ms [Q: G]
time 28642ms: Process G started using the CPU for 113ms burst [Q: empty]
time 28731ms: Process D completed I/O; added to ready queue [Q: D]
time 28755ms: Process G completed a CPU burst; 17 bursts to go [Q: D]
time 28755ms: Process G switching out of CPU; will block on I/O until time 31017ms [Q: D]
time 28759ms: Process D started using the CPU for 256ms burst [Q: empty]
time 28900ms: Process F completed I/O; added to ready queue [Q: F]
time 29015ms: Process D completed a CPU burst; 60 bursts to go [Q: F]
time 29015ms: Process D switching out of CPU; will block on I/O until time 29107ms [Q: F]
time 29019ms: Process F started using the CPU for 175ms burst [Q: empty]
time 29107ms: Process D completed I/O; added to ready queue [Q: D]
time 29150ms: Process B completed I/O; added to ready queue [Q: D B]
time 29194ms: Process F completed a CPU burst; 33 bursts to go [Q: D B]
time 29194ms: Process F switching out of CPU; will block on I/O until time 30796ms [Q: D B]
time 29198ms: Process D started using the CPU for 61ms burst [Q: B]
time 29259ms: Process D completed a CPU burst; 59 bursts to go [Q: B]
time 29259ms: Process D switching out of CPU; will block on I/O until time 31621ms [Q: B]
time 29263ms: Process B started using the CPU for 46ms burst [Q: empty]
time 29309ms: Process B completed a CPU burst; 33 bursts to go [Q: empty]
time 29309ms: Process B switching out of CPU; will block on I/O until time 29691ms [Q: empty]
time 29691ms: Process B completed I/O; added to ready queue [Q: B]
time 29693ms: Process B started using the CPU for 4ms burst [Q: empty]
time 29697ms: Process B completed a CPU burst; 32 bursts to go [Q: empty]
time 29697ms: Process B switching out of CPU; will block on I/O until time 29849ms [Q: empty]
time 29849ms: Process B completed I/O; added to ready queue [Q: B]
time 29851ms: Process B started using the CPU for 6ms burst [Q: empty]
time 29857ms: Process B completed a CPU burst; 31 bursts to go [Q: empty]
time 29857ms: Process B switching out of CPU; will block on I/O until time 30949ms [Q: empty]
time 30330ms: Process H completed I/O; added to ready queue [Q: H]
time 30332ms: Process H started using the CPU for 308ms burst [Q: empty]
time 30533ms: Process C completed I/O; added to ready queue [Q: C]
time 30640ms: Process H completed a CPU burst; 56 bursts to go [Q: C]
time 30640ms: Process H switching out of CPU; will block on I/O until time 31522ms [Q: C]
time 30644ms: Process C started using the CPU for 108ms burst [Q: empty]
time 30752ms: Process C completed a CPU burst; 11 bursts to go [Q: empty]
time 30752ms: Process C switching out of CPU; will block on I/O until time 35314ms [Q: empty]
time 30796ms: Process F completed I/O; added to ready queue [Q: F]
time 30798ms: Process F started using the CPU for 23ms burst [Q: empty]
time 30821ms: Process F completed a CPU burst; 32 bursts to go [Q: empty]
time 30821ms: Process F switching out of CPU; will block on I/O until time 32223ms [Q: empty]
time 30949ms: Process B completed I/O; added to ready queue [Q: B]
time 30951ms: Process B started using the CPU for 24ms burst [Q: empty]
time 30975ms: Process B completed a CPU burst; 30 bursts to go [Q: empty]
time 30975ms: Process B switching out of CPU; will block on I/O until time 31617ms [Q: empty]
time 31017ms: Process G completed I/O; added to ready queue [Q: G]
time 31019ms: Process G started using the CPU for 164ms burst [Q: empty]
time 31183ms: Process G completed a CPU burst; 16 bursts to go [Q: empty]
time 31183ms: Process G switching out of CPU; will block on I/O until time 33215ms [Q: empty]
time 31522ms: Process H completed I/O; added to ready queue [Q: H]
time 31524ms: Process H started using the CPU for 36ms burst [Q: empty]
time 31560ms: Process H completed a CPU burst; 55 bursts to go [Q: empty]
time 31560ms: Process H switching out of CPU; will block on I/O until time 33972ms [Q: empty]
time 31617ms: Process B completed I/O; added to ready queue [Q: B]
time 31619ms: Process B started using the CPU for 101ms burst [Q: empty]
time 31621ms: Process D completed I/O; added to ready queue [Q: D]
time 31706ms: Process E completed I/O; added to ready queue [Q: D E]
time 31720ms: Process B completed a CPU burst; 29 bursts to go [Q: D E]
time 31720ms: Process B switching out of CPU; will block on I/O until time 32632ms [Q: D E]
time 31724ms: Process D started using the CPU for 2ms burst [Q: E]
time 31726ms: Process D completed a CPU burst; 58 bursts to go [Q: E]
time 31726ms: Process D switching out of CPU; will block on I/O until time 33358ms [Q: E]
time 31730ms: Process E started using the CPU for 29ms burst [Q: empty]
time 31759ms: Process E completed a CPU burst; 52 bursts to go [Q: empty]
time 31759ms: Process E switching out of CPU; will block on I/O until time 32991ms [Q: empty]
time 32223ms: Process F completed I/O; added to ready queue [Q: F]
time 32225ms: Process F started using the CPU for 107ms burst [Q: empty]
time 32332ms: Process F completed a CPU burst; 31 bursts to go [Q: empty]
time 32332ms: Process F switching out of CPU; will block on I/O until time 32504ms [Q: empty]
time 32504ms: Process F completed I/O; added to ready queue [Q: F]
time 32506ms: Process F started using the CPU for 130ms burst [Q: empty]
time 32632ms: Process B completed I/O; added to ready queue [Q: B]
time 32636ms: Process F completed a CPU burst; 30 bursts to go [Q: B]
time 32636ms: Process F switching out of CPU; will block on I/O until time 32748ms [Q: B]
time 32640ms: Process B started using the CPU for 98ms burst [Q: empty]
time 32738ms: Process B completed a CPU burst; 28 bursts to go [Q: empty]
time 32738ms: Process B switching out of CPU; will block on I/O until time 35250ms [Q: empty]
time 32748ms: Process F completed I/O; added to ready queue [Q: F]
time 32750ms: Process F started using the CPU for 204ms burst [Q: empty]
time 32954ms: Process F completed a CPU burst; 29 bursts to go [Q: empty]
time 32954ms: Process F switching out of CPU; will block on I/O until time 34966ms [Q: empty]
time 32991ms: Process E completed I/O; added to ready queue [Q: E]
time 32993ms: Process E started using the CPU for 152ms burst [Q: empty]
time 33145ms: Process E completed a CPU burst; 51 bursts to go [Q: empty]
time 33145ms: Process E switching out of CPU; will block on I/O until time 33417ms [Q: empty]
time 33215ms: Process G completed I/O; added to ready queue [Q: G]
time 33217ms: Process G started using the CPU for 2ms burst [Q: empty]
time 33219ms: Process G completed a CPU burst; 15 bursts to go [Q: empty]
time 33219ms: Process G switching out of CPU; will block on I/O until time 36281ms [Q: empty]
time 33358ms: Process D completed I/O; added to ready queue [Q: D]
time 33360ms: Process D started using the CPU for 102ms burst [Q: empty]
time 33417ms: Process E completed I/O; added to ready queue [Q: E]
time 33462ms: Process D completed a CPU burst; 57 bursts to go [Q: E]
time 33462ms: Process D switching out of CPU; will block on I/O until time 35434ms [Q: E]
time 33466ms: Process E started using the CPU for 128ms burst [Q: empty]
time 33594ms: Process E completed a CPU burst; 50 bursts to go [Q: empty]
time 33594ms: Process E switching out of CPU; will block on I/O until time 34316ms [Q: empty]
time 33972ms: Process H completed I/O; added to ready queue [Q: H]
time 33974ms: Process H started using the CPU for 186ms burst [Q: empty]
time 34160ms: Process H completed a CPU burst; 54 bursts to go [Q: empty]
time 34160ms: Process H switching out of CPU; will block on I/O until time 34542ms [Q: empty]
time 34316ms: Process E completed I/O; added to ready queue [Q: E]
time 34318ms: Process E started using the CPU for 37ms burst [Q: empty]
time 34355ms: Process E completed a CPU burst; 49 bursts to go [Q: empty]
time 34355ms: Process E switching out of CPU; will block on I/O until time 35927ms [Q: empty]
time 34542ms: Process H completed I/O; added to ready queue [Q: H]
time 34544ms: Process H started using the CPU for 77ms burst [Q: empty]
time 34621ms: Process H completed a CPU burst; 53 bursts to go [Q: empty]
time 34621ms: Process H switching out of CPU; will block on I/O until time 36553ms [Q: empty]
time 34966ms: Process F completed I/O; added to ready queue [Q: F]
time 34968ms: Process F started using the CPU for 338ms burst [Q: empty]
time 35250ms: Process B completed I/O; added to ready queue [Q: B]
time 35306ms: Process F completed a CPU burst; 28 bursts to go [Q: B]
time 35306ms: Process F switching out of CPU; will block on I/O until time 36298ms [Q: B]
time 35310ms: Process B started using the CPU for 78ms burst [Q: empty]
time 35314ms: Process C completed I/O; added to ready queue [Q: C]
time 35388ms: Process B completed a CPU burst; 27 bursts to go [Q: C]
time 35388ms: Process B switching out of CPU; will block on I/O until time 36450ms [Q: C]
time 35392ms: Process C started using the CPU for 23ms burst [Q: empty]
time 35415ms: Process C completed a CPU burst; 10 bursts to go [Q: empty]
time 35415ms: Process C switching out of CPU; will block on I/O until time 35947ms [Q: empty]
time 35434ms: Process D completed I/O; added to ready queue [Q: D]
time 35436ms: Process D started using the CPU for 19ms burst [Q: empty]
time 35455ms: Process D completed a CPU burst; 56 bursts to go [Q: empty]
time 35455ms: Process D switching out of CPU; will block on I/O until time 35597ms [Q: empty]
time 35597ms: Process D completed I/O; added to ready queue [Q: D]
time 35599ms: Process D started using the CPU for 48ms burst [Q: empty]
time 35647ms: Process D completed a CPU burst; 55 bursts to go [Q: empty]
time 35647ms: Process D switching out of CPU; will block on I/O until time 36089ms [Q: empty]
time 35927ms: Process E completed I/O; added to ready queue [Q: E]
time 35929ms: Process E started using the CPU for 105ms burst [Q: empty]
time 35947ms: Process C completed I/O; added to ready queue [Q: C]
time 36034ms: Process E completed a CPU burst; 48 bursts to go [Q: C]
time 36034ms: Process E switching out of CPU; will block on I/O until time 37286ms [Q: C]
time 36038ms: Process C started using the CPU for 70ms burst [Q: empty]
time 36089ms: Process D completed I/O; added to ready queue [Q: D]
time 36108ms: Process C completed a CPU burst; 9 bursts to go [Q: D]
time 36108ms: Process C switching out of CPU; will block on I/O until time 37560ms [Q: D]
time 36112ms: Process D started using the CPU for 401ms burst [Q: empty]
time 36281ms: Process G completed I/O; added to ready queue [Q: G]
time 36298ms: Process F completed I/O; added to ready queue [Q: G F]
time 36450ms: Process B completed I/O; added to ready queue [Q: G F B]
time 36513ms: Process D completed a CPU burst; 54 bursts to go [Q: G F B]
time 36513ms: Process D switching out of CPU; will block on I/O until time 38005ms [Q: G F B]
time 36517ms: Process G started using the CPU for 35ms burst [Q: F B]
time 36552ms: Process G completed a CPU burst; 14 bursts to go [Q: F B]
time 36552ms: Process G switching out of CPU; will block on I/O until time 40674ms [Q: F B]
time 36553ms: Process H completed I/O; added to ready queue [Q: F B H]
time 36556ms: Process F started using the CPU for 125ms burst [Q: B H]
time 36681ms: Process F completed a CPU burst; 27 bursts to go [Q: B H]
time 36681ms: Process F switching out of CPU; will block on I/O until time 37713ms [Q: B H]
time 36685ms: Process B started using the CPU for 49ms burst [Q: H]
time 36734ms: Process B completed a CPU burst; 26 bursts to go [Q: H]
time 36734ms: Process B switching out of CPU; will block on I/O until time 39706ms [Q: H]
time 36738ms: Process H started using the CPU for 294ms burst [Q: empty]
time 37032ms: Process H completed a CPU burst; 52 bursts to go [Q: empty]
time 37032ms: Process H switching out of CPU; will block on I/O until time 37264ms [Q: empty]
time 37264ms: Process H completed I/O; added to ready queue [Q: H]
time 37266ms: Process H started using the CPU for 21ms burst [Q: empty]
time 37286ms: Process E completed I/O; added to ready queue [Q: E]
time 37287ms: Process H completed a CPU burst; 51 bursts to go [Q: E]
time 37287ms: Process H switching out of CPU; will block on I/O until time 37789ms [Q: E]
time 37291ms: Process E started using the CPU for 30ms burst [Q: empty]
time 37321ms: Process E completed a CPU burst; 47 bursts to go [Q: empty]
time 37321ms: Process E switching out of CPU; will block on I/O until time 38063ms [Q: empty]
time 37560ms: Process C completed I/O; added to ready queue [Q: C]
time 37562ms: Process C started using the CPU for 66ms burst [Q: empty]
time 37628ms: Process C completed a CPU burst; 8 bursts to go [Q: empty]
time 37628ms: Process C switching out of CPU; will block on I/O until time 38490ms [Q: empty]
time 37713ms: Process F completed I/O; added to ready queue [Q: F]
time 37715ms: Process F started using the CPU for 306ms burst [Q: empty]
time 37789ms: Process H completed I/O; added to ready queue [Q: H]
time 38005ms: Process D completed I/O; added to ready queue [Q: H D]
time 38021ms: Process F completed a CPU burst; 26 bursts to go [Q: H D]
time 38021ms: Process F switching out of CPU; will block on I/O until time 39133ms [Q: H D]
time 38025ms: Process H started using the CPU for 263ms burst [Q: D]
time 38063ms: Process E completed I/O; added to ready queue [Q: D E]
time 38288ms: Process H completed a CPU burst; 50 bursts to go [Q: D E]
time 38288ms: Process H switching out of CPU; will block on I/O until time 43060ms [Q: D E]
time 38292ms: Process D started using the CPU for 25ms burst [Q: E]
time 38317ms: Process D completed a CPU burst; 53 bursts to go [Q: E]
time 38317ms: Process D switching out of CPU; will block on I/O until time 43119ms [Q: E]
time 38321ms: Process E started using the CPU for 10ms burst [Q: empty]
time 38331ms: Process E completed a CPU burst; 46 bursts to go [Q: empty]
time 38331ms: Process E switching out of CPU; will block on I/O until time 39163ms [Q: empty]
time 38490ms: Process C completed I/O; added to ready queue [Q: C]
time 38492ms: Process C started using the CPU for 106ms burst [Q: empty]
time 38598ms: Process C completed a CPU burst; 7 bursts to go [Q: empty]
time 38598ms: Process C switching out of CPU; will block on I/O until time 42410ms [Q: empty]
time 39133ms: Process F completed I/O; added to ready queue [Q: F]
time 39135ms: Process F started using the CPU for 11ms burst [Q: empty]
time 39146ms: Process F completed a CPU burst; 25 bursts to go [Q: empty]
time 39146ms: Process F switching out of CPU; will block on I/O until time 39688ms [Q: empty]
time 39163ms: Process E completed I/O; added to ready queue [Q: E]
time 39165ms: Process E started using the CPU for 6ms burst [Q: empty]
time 39171ms: Process E completed a CPU burst; 45 bursts to go [Q: empty]
time 39171ms: Process E switching out of CPU; will block on I/O until time 40173ms [Q: empty]
time 39688ms: Process F completed I/O; added to ready queue [Q: F]
time 39690ms: Process F started using the CPU for 8ms burst [Q: empty]
time 39698ms: Process F completed a CPU burst; 24 bursts to go [Q: empty]
time 39698ms: Process F switching out of CPU; will block on I/O until time 39810ms [Q: empty]
time 39706ms: Process B completed I/O; added to ready queue [Q: B]
time 39708ms: Process B started using the CPU for 93ms burst [Q: empty]
time 39801ms: Process B completed a CPU burst; 25 bursts to go [Q: empty]
time 39801ms: Process B switching out of CPU; will block on I/O until time 40993ms [Q: empty]
time 39810ms: Process F completed I/O; added to ready queue [Q: F]
time 39812ms: Process F started using the CPU for 71ms burst [Q: empty]
time 39883ms: Process F completed a CPU burst; 23 bursts to go [Q: empty]
time 39883ms: Process F switching out of CPU; will block on I/O until time 41195ms [Q: empty]
time 40173ms: Process E completed I/O; added to ready queue [Q: E]
time 40175ms: Process E started using the CPU for 27ms burst [Q: empty]
time 40202ms: Process E completed a CPU burst; 44 bursts to go [Q: empty]
time 40202ms: Process E switching out of CPU; will block on I/O until time 40624ms [Q: empty]
time 40624ms: Process E completed I/O; added to ready queue [Q: E]
time 40626ms: Process E started using the CPU for 53ms burst [Q: empty]
time 40674ms: Process G completed I/O; added to ready queue [Q: G]
time 40679ms: Process E completed a CPU burst; 43 bursts to go [Q: G]
time 40679ms: Process E switching out of CPU; will block on I/O until time 42021ms [Q: G]
time 40683ms: Process G started using the CPU for 40ms burst [Q: empty]
time 40723ms: Process G completed a CPU burst; 13 bursts to go [Q: empty]
time 40723ms: Process G switching out of CPU; will block on I/O until time 41255ms [Q: empty]
time 40993ms: Process B completed I/O; added to ready queue [Q: B]
time 40995ms: Process B started using the CPU for 347ms burst [Q: empty]
time 41195ms: Process F completed I/O; added to ready queue [Q: F]
time 41255ms: Process G completed I/O; added to ready queue [Q: F G]
time 41342ms: Process B completed a CPU burst; 24 bursts to go [Q: F G]
time 41342ms: Process B switching out of CPU; will block on I/O until time 41584ms [Q: F G]
time 41346ms: Process F started using the CPU for 222ms burst [Q: G]
time 41568ms: Process F completed a CPU burst; 22 bursts to go [Q: G]
time 41568ms: Process F switching out of CPU; will block on I/O until time 41810ms [Q: G]
time 41572ms: Process G started using the CPU for 388ms burst [Q: empty]
time 41584ms: Process B completed I/O; added to ready queue [Q: B]
time 41810ms: Process F completed I/O; added to ready queue [Q: B F]
time 41960ms: Process G completed a CPU burst; 12 bursts to go [Q: B F]
time 41960ms: Process G switching out of CPU; will block on I/O until time 46172ms [Q: B F]
time 41964ms: Process B started using the CPU for 80ms burst [Q: F]
time 42021ms: Process E completed I/O; added to ready queue [Q: F E]
time 42044ms: Process B completed a CPU burst; 23 bursts to go [Q: F E]
time 42044ms: Process B switching out of CPU; will block on I/O until time 44806ms [Q: F E]
time 42048ms: Process F started using the CPU for 21ms burst [Q: E]
time 42069ms: Process F completed a CPU burst; 21 bursts to go [Q: E]
time 42069ms: Process F switching out of CPU; will block on I/O until time 42421ms [Q: E]
time 42073ms: Process E started using the CPU for 328ms burst [Q: empty]
time 42401ms: Process E completed a CPU burst; 42 bursts to go [Q: empty]
time 42401ms: Process E switching out of CPU; will block on I/O until time 42663ms [Q: empty]
time 42410ms: Process C completed I/O; added to ready queue [Q: C]
time 42412ms: Process C started using the CPU for 41ms burst [Q: empty]
time 42421ms: Process F completed I/O; added to ready queue [Q: F]
time 42453ms: Process C completed a CPU burst; 6 bursts to go [Q: F]
time 42453ms: Process C switching out of CPU; will block on I/O until time 43005ms [Q: F]
time 42457ms: Process F started using the CPU for 61ms burst [Q: empty]
time 42518ms: Process F completed a CPU burst; 20 bursts to go [Q: empty]
time 42518ms: Process F switching out of CPU; will block on I/O until time 42540ms [Q: empty]
time 42540ms: Process F completed I/O; added to ready queue [Q: F]
time 42542ms: Process F started using the CPU for 13ms burst [Q: empty]
time 42555ms: Process F completed a CPU burst; 19 bursts to go [Q: empty]
time 42555ms: Process F switching out of CPU; will block on I/O until time 43247ms [Q: empty]
time 42663ms: Process E completed I/O; added to ready queue [Q: E]
time 42665ms: Process E started using the CPU for 155ms burst [Q: empty]
time 42820ms: Process E completed a CPU burst; 41 bursts to go [Q: empty]
time 42820ms: Process E switching out of CPU; will block on I/O until time 43282ms [Q: empty]
time 43005ms: Process C completed I/O; added to ready queue [Q: C]
time 43007ms: Process C started using the CPU for 23ms burst [Q: empty]
time 43030ms: Process C completed a CPU burst; 5 bursts to go [Q: empty]
time 43030ms: Process C switching out of CPU; will block on I/O until time 44082ms [Q: empty]
time 43060ms: Process H completed I/O; added to ready queue [Q: H]
time 43062ms: Process H started using the CPU for 103ms burst [Q: empty]
time 43119ms: Process D completed I/O; added to ready queue [Q: D]
time 43165ms: Process H completed a CPU burst; 49 bursts to go [Q: D]
time 43165ms: Process H switching out of CPU; will block on I/O until time 46307ms [Q: D]
time 43169ms: Process D started using the CPU for 68ms burst [Q: empty]
time 43237ms: Process D completed a CPU burst; 52 bursts to go [Q: empty]
time 43237ms: Process D switching out of CPU; will block on I/O until time 44409ms [Q: empty]
time 43247ms: Process F completed I/O; added to ready queue [Q: F]
time 43249ms: Process F started using the CPU for 72ms burst [Q: empty]
time 43282ms: Process E completed I/O; added to ready queue [Q: E]
time 43321ms: Process F completed a CPU burst; 18 bursts to go [Q: E]
time 43321ms: Process F switching out of CPU; will block on I/O until time 44033ms [Q: E]
time 43325ms: Process E started using the CPU for 64ms burst [Q: empty]
time 43389ms: Process E completed a CPU burst; 40 bursts to go [Q: empty]
time 43389ms: Process E switching out of CPU; will block on I/O until time 44281ms [Q: empty]
time 44033ms: Process F completed I/O; added to ready queue [Q: F]
time 44035ms: Process F started using the CPU for 3ms burst [Q: empty]
time 44038ms: Process F completed a CPU burst; 17 bursts to go [Q: empty]
time 44038ms: Process F switching out of CPU; will block on I/O until time 44180ms [Q: empty]
time 44082ms: Process C completed I/O; added to ready queue [Q: C]
time 44084ms: Process C started using the CPU for 243ms burst [Q: empty]
time 44180ms: Process F completed I/O; added to ready queue [Q: F]
time 44281ms: Process E completed I/O; added to ready queue [Q: F E]
time 44327ms: Process C completed a CPU burst; 4 bursts to go [Q: F E]
time 44327ms: Process C switching out of CPU; will block on I/O until time 44859ms [Q: F E]
time 44331ms: Process F started using the CPU for 44ms burst [Q: E]
time 44375ms: Process F completed a CPU burst; 16 bursts to go [Q: E]
time 44375ms: Process F switching out of CPU; will block on I/O until time 46147ms [Q: E]
time 44379ms: Process E started using the CPU for 54ms burst [Q: empty]
time 44409ms: Process D completed I/O; added to ready queue [Q: D]
time 44433ms: Process E completed a CPU burst; 39 bursts to go [Q: D]
time 44433ms: Process E switching out of CPU; will block on I/O until time 46495ms [Q: D]
time 44437ms: Process D started using the CPU for 18ms burst [Q: empty]
time 44455ms: Process D completed a CPU burst; 51 bursts to go [Q: empty]
time 44455ms: Process D switching out of CPU; will block on I/O until time 45007ms [Q: empty]
time 44806ms: Process B completed I/O; added to ready queue [Q: B]
time 44808ms: Process B started using the CPU for 182ms burst [Q: empty]
time 44859ms: Process C completed I/O; added to ready queue [Q: C]
time 44990ms: Process B completed a CPU burst; 22 bursts to go [Q: C]
time 44990ms: Process B switching out of CPU; will block on I/O until time 45222ms [Q: C]
time 44994ms: Process C started using the CPU for 65ms burst [Q: empty]
time 45007ms: Process D completed I/O; added to ready queue [Q: D]
time 45059ms: Process C completed a CPU burst; 3 bursts to go [Q: D]
time 45059ms: Process C switching out of CPU; will block on I/O until time 47271ms [Q: D]
time 45063ms: Process D started using the CPU for 15ms burst [Q: empty]
time 45078ms: Process D completed a CPU burst; 50 bursts to go [Q: empty]
time 45078ms: Process D switching out of CPU; will block on I/O until time 45160ms [Q: empty]
time 45160ms: Process D completed I/O; added to ready queue [Q: D]
time 45162ms: Process D started using the CPU for 8ms burst [Q: empty]
time 45170ms: Process D completed a CPU burst; 49 bursts to go [Q: empty]
time 45170ms: Process D switching out of CPU; will block on I/O until time 45202ms [Q: empty]
time 45202ms: Process D completed I/O; added to ready queue [Q: D]
time 45204ms: Process D started using the CPU for 24ms burst [Q: empty]
time 45222ms: Process B completed I/O; added to ready queue [Q: B]
time 45228ms: Process D completed a CPU burst; 48 bursts to go [Q: B]
time 45228ms: Process D switching out of CPU; will block on I/O until time 46340ms [Q: B]
time 45232ms: Process B started using the CPU for 415ms burst [Q: empty]
time 45647ms: Process B completed a CPU burst; 21 bursts to go [Q: empty]
time 45647ms: Process B switching out of CPU; will block on I/O until time 46569ms [Q: empty]
time 46147ms: Process F completed I/O; added to ready queue [Q: F]
time 46149ms: Process F started using the CPU for 85ms burst [Q: empty]
time 46172ms: Process G completed I/O; added to ready queue [Q: G]
time 46234ms: Process F completed a CPU burst; 15 bursts to go [Q: G]
time 46234ms: Process F switching out of CPU; will block on I/O until time 47706ms [Q: G]
time 46238ms: Process G started using the CPU for 86ms burst [Q: empty]
time 46307ms: Process H completed I/O; added to ready queue [Q: H]
time 46324ms: Process G completed a CPU burst; 11 bursts to go [Q: H]
time 46324ms: Process G switching out of CPU; will block on I/O until time 46776ms [Q: H]
time 46328ms: Process H started using the CPU for 11ms burst [Q: empty]
time 46339ms: Process H completed a CPU burst; 48 bursts to go [Q: empty]
time 46339ms: Process H switching out of CPU; will block on I/O until time 47501ms [Q: empty]
time 46340ms: Process D completed I/O; added to ready queue [Q: D]
time 46343ms: Process D started using the CPU for 13ms burst [Q: empty]
time 46356ms: Process D completed a CPU burst; 47 bursts to go [Q: empty]
time 46356ms: Process D switching out of CPU; will block on I/O until time 47098ms [Q: empty]
time 46495ms: Process E completed I/O; added to ready queue [Q: E]
time 46497ms: Process E started using the CPU for 9ms burst [Q: empty]
time 46506ms: Process E completed a CPU burst; 38 bursts to go [Q: empty]
time 46506ms: Process E switching out of CPU; will block on I/O until time 46598ms [Q: empty]
time 46569ms: Process B completed I/O; added to ready queue [Q: B]
time 46571ms: Process B started using the CPU for 281ms burst [Q: empty]
time 46598ms: Process E completed I/O; added to ready queue [Q: E]
time 46776ms: Process G completed I/O; added to ready queue [Q: E G]
time 46852ms: Process B completed a CPU burst; 20 bursts to go [Q: E G]
time 46852ms: Process B switching out of CPU; will block on I/O until time 47474ms [Q: E G]
time 46856ms: Process E started using the CPU for 141ms burst [Q: G]
time 46997ms: Process E completed a CPU burst; 37 bursts to go [Q: G]
time 46997ms: Process E switching out of CPU; will block on I/O until time 49879ms [Q: G]
time 47001ms: Process G started using the CPU for 41ms burst [Q: empty]
time 47042ms: Process G completed a CPU burst; 10 bursts to go [Q: empty]
time 47042ms: Process G switching out of CPU; will block on I/O until time 47564ms [Q: empty]
time 47098ms: Process D completed I/O; added to ready queue [Q: D]
time 47100ms: Process D started using the CPU for 29ms burst [Q: empty]
time 47129ms: Process D completed a CPU burst; 46 bursts to go [Q: empty]
time 47129ms: Process D switching out of CPU; will block on I/O until time 47241ms [Q: empty]
time 47241ms: Process D completed I/O; added to ready queue [Q: D]
time 47243ms: Process D started using the CPU for 26ms burst [Q: empty]
time 47269ms: Process D completed a CPU burst; 45 bursts to go [Q: empty]
time 47269ms: Process D switching out of CPU; will block on I/O until time 47331ms [Q: empty]
time 47271ms: Process C completed I/O; added to ready queue [Q: C]
time 47273ms: Process C started using the CPU for 62ms burst [Q: empty]
time 47331ms: Process D completed I/O; added to ready queue [Q: D]
time 47335ms: Process C completed a CPU burst; 2 bursts to go [Q: D]
time 47335ms: Process C switching out of CPU; will block on I/O until time 47917ms [Q: D]
time 47339ms: Process D started using the CPU for 138ms burst [Q: empty]
time 47474ms: Process B completed I/O; added to ready queue [Q: B]
time 47477ms: Process D completed a CPU burst; 44 bursts to go [Q: B]
time 47477ms: Process D switching out of CPU; will block on I/O until time 50039ms [Q: B]
time 47481ms: Process B started using the CPU for 77ms burst [Q: empty]
time 47501ms: Process H completed I/O; added to ready queue [Q: H]
time 47558ms: Process B completed a CPU burst; 19 bursts to go [Q: H]
time 47558ms: Process B switching out of CPU; will block on I/O until time 48140ms [Q: H]
time 47562ms: Process H started using the CPU for 75ms burst [Q: empty]
time 47564ms: Process G completed I/O; added to ready queue [Q: G]
time 47637ms: Process H completed a CPU burst; 47 bursts to go [Q: G]
time 47637ms: Process H switching out of CPU; will block on I/O until time 48059ms [Q: G]
time 47641ms: Process G started using the CPU for 146ms burst [Q: empty]
time 47706ms: Process F completed I/O; added to ready queue [Q: F]
time 47787ms: Process G completed a CPU burst; 9 bursts to go [Q: F]
time 47787ms: Process G switching out of CPU; will block on I/O until time 48369ms [Q: F]
time 47791ms: Process F started using the CPU for 48ms burst [Q: empty]
time 47839ms: Process F completed a CPU burst; 14 bursts to go [Q: empty]
time 47839ms: Process F switching out of CPU; will block on I/O until time 49621ms [Q: empty]
time 47917ms: Process C completed I/O; added to ready queue [Q: C]
time 47919ms: Process C started using the CPU for 56ms burst [Q: empty]
time 47975ms: Process C completed a CPU burst; 1 burst to go [Q: empty]
time 47975ms: Process C switching out of CPU; will block on I/O until time 50607ms [Q: empty]
time 48059ms: Process H completed I/O; added to ready queue [Q: H]
time 48061ms: Process H started using the CPU for 158ms burst [Q: empty]
time 48140ms: Process B completed I/O; added to ready queue [Q: B]
time 48219ms: Process H completed a CPU burst; 46 bursts to go [Q: B]
time 48219ms: Process H switching out of CPU; will block on I/O until time 48411ms [Q: B]
time 48223ms: Process B started using the CPU for 56ms burst [Q: empty]
time 48279ms: Process B completed a CPU burst; 18 bursts to go [Q: empty]
time 48279ms: Process B switching out of CPU; will block on I/O until time 48941ms [Q: empty]
time 48369ms: Process G completed I/O; added to ready queue [Q: G]
time 48371ms: Process G started using the CPU for 54ms burst [Q: empty]
time 48411ms: Process H completed I/O; added to ready queue [Q: H]
time 48425ms: Process G completed a CPU burst; 8 bursts to go [Q: H]
time 48425ms: Process G switching out of CPU; will block on I/O until time 49107ms [Q: H]
time 48429ms: Process H started using the CPU for 66ms burst [Q: empty]
time 48495ms: Process H completed a CPU burst; 45 bursts to go [Q: empty]
time 48495ms: Process H switching out of CPU; will block on I/O until time 48507ms [Q: empty]
time 48507ms: Process H completed I/O; added to ready queue [Q: H]
time 48509ms: Process H started using the CPU for 71ms burst [Q: empty]
time 48580ms: Process H completed a CPU burst; 44 bursts to go [Q: empty]
time 48580ms: Process H switching out of CPU; will block on I/O until time 49522ms [Q: empty]
time 48941ms: Process B completed I/O; added to ready queue [Q: B]
time 48943ms: Process B started using the CPU for 53ms burst [Q: empty]
time 48996ms: Process B completed a CPU burst; 17 bursts to go [Q: empty]
time 48996ms: Process B switching out of CPU; will block on I/O until time 49308ms [Q: empty]
time 49107ms: Process G completed I/O; added to ready queue [Q: G]
time 49109ms: Process G started using the CPU for 39ms burst [Q: empty]
time 49148ms: Process G completed a CPU burst; 7 bursts to go [Q: empty]
time 49148ms: Process G switching out of CPU; will block on I/O until time 49750ms [Q: empty]
time 49308ms: Process B completed I/O; added to ready queue [Q: B]
time 49310ms: Process B started using the CPU for 77ms burst [Q: empty]
time 49387ms: Process B completed a CPU burst; 16 bursts to go [Q: empty]
time 49387ms: Process B switching out of CPU; will block on I/O until time 50499ms [Q: empty]
time 49522ms: Process H completed I/O; added to ready queue [Q: H]
time 49524ms: Process H started using the CPU for 4ms burst [Q: empty]
time 49528ms: Process H completed a CPU burst; 43 bursts to go [Q: empty]
time 49528ms: Process H switching out of CPU; will block on I/O until time 49990ms [Q: empty]
time 49621ms: Process F completed I/O; added to ready queue [Q: F]
time 49623ms: Process F started using the CPU for 4ms burst [Q: empty]
time 49627ms: Process F completed a CPU burst; 13 bursts to go [Q: empty]
time 49627ms: Process F switching out of CPU; will block on I/O until time 52729ms [Q: empty]
time 49750ms: Process G completed I/O; added to ready queue [Q: G]
time 49752ms: Process G started using the CPU for 174ms burst [Q: empty]
time 49879ms: Process E completed I/O; added to ready queue [Q: E]
time 49926ms: Process G completed a CPU burst; 6 bursts to go [Q: E]
time 49926ms: Process G switching out of CPU; will block on I/O until time 50768ms [Q: E]
time 49930ms: Process E started using the CPU for 42ms burst [Q: empty]
time 49972ms: Process E completed a CPU burst; 36 bursts to go [Q: empty]
time 49972ms: Process E switching out of CPU; will block on I/O until time 50314ms [Q: empty]
time 49990ms: Process H completed I/O; added to ready queue [Q: H]
time 49992ms: Process H started using the CPU for 35ms burst [Q: empty]
time 50027ms: Process H completed a CPU burst; 42 bursts to go [Q: empty]
time 50027ms: Process H switching out of CPU; will block on I/O until time 51949ms [Q: empty]
time 50039ms: Process D completed I/O; added to ready queue [Q: D]
time 50041ms: Process D started using the CPU for 58ms burst [Q: empty]
time 50099ms: Process D completed a CPU burst; 43 bursts to go [Q: empty]
time 50099ms: Process D switching out of CPU; will block on I/O until time 51381ms [Q: empty]
time 50314ms: Process E completed I/O; added to ready queue [Q: E]
time 50316ms: Process E started using the CPU for 98ms burst [Q: empty]
time 50414ms: Process E completed a CPU burst; 35 bursts to go [Q: empty]
time 50414ms: Process E switching out of CPU; will block on I/O until time 51366ms [Q: empty]
time 50499ms: Process B completed I/O; added to ready queue [Q: B]
time 50501ms: Process B started using the CPU for 197ms burst [Q: empty]
time 50607ms: Process C completed I/O; added to ready queue [Q: C]
time 50698ms: Process B completed a CPU burst; 15 bursts to go [Q: C]
time 50698ms: Process B switching out of CPU; will block on I/O until time 52290ms [Q: C]
time 50702ms: Process C started using the CPU for 2ms burst [Q: empty]
time 50704ms: Process C terminated [Q: empty]
time 50768ms: Process G completed I/O; added to ready queue [Q: G]
time 50770ms: Process G started using the CPU for 127ms burst [Q: empty]
time 50897ms: Process G completed a CPU burst; 5 bursts to go [Q: empty]
time 50897ms: Process G switching out of CPU; will block on I/O until time 51399ms [Q: empty]
time 51366ms: Process E completed I/O; added to ready queue [Q: E]
time 51368ms: Process E started using the CPU for 77ms burst [Q: empty]
time 51381ms: Process D completed I/O; added to ready queue [Q: D]
time 51399ms: Process G completed I/O; added to ready queue [Q: D G]
time 51445ms: Process E completed a CPU burst; 34 bursts to go [Q: D G]
time 51445ms: Process E switching out of CPU; will block on I/O until time 51737ms [Q: D G]
time 51449ms: Process D started using the CPU for 101ms burst [Q: G]
time 51550ms: Process D completed a CPU burst; 42 bursts to go [Q: G]
time 51550ms: Process D switching out of CPU; will block on I/O until time 53862ms [Q: G]
time 51554ms: Process G started using the CPU for 2ms burst [Q: empty]
time 51556ms: Process G completed a CPU burst; 4 bursts to go [Q: empty]
time 51556ms: Process G switching out of CPU; will block on I/O until time 51978ms [Q: empty]
time 51737ms: Process E completed I/O; added to ready queue [Q: E]
time 51739ms: Process E started using the CPU for 182ms burst [Q: empty]
time 51921ms: Process E completed a CPU burst; 33 bursts to go [Q: empty]
time 51921ms: Process E switching out of CPU; will block on I/O until time 52413ms [Q: empty]
time 51949ms: Process H completed I/O; added to ready queue [Q: H]
time 51951ms: Process H started using the CPU for 20ms burst [Q: empty]
time 51971ms: Process H completed a CPU burst; 41 bursts to go [Q: empty]
time 51971ms: Process H switching out of CPU; will block on I/O until time 52613ms [Q: empty]
time 51978ms: Process G completed I/O; added to ready queue [Q: G]
time 51980ms: Process G started using the CPU for 4ms burst [Q: empty]
time 51984ms: Process G completed a CPU burst; 3 bursts to go [Q: empty]
time 51984ms: Process G switching out of CPU; will block on I/O until time 52586ms [Q: empty]
time 52290ms: Process B completed I/O; added to ready queue [Q: B]
time 52292ms: Process B started using the CPU for 5ms burst [Q: empty]
time 52297ms: Process B completed a CPU burst; 14 bursts to go [Q: empty]
time 52297ms: Process B switching out of CPU; will block on I/O until time 52669ms [Q: empty]
time 52413ms: Process E completed I/O; added to ready queue [Q: E]
time 52415ms: Process E started using the CPU for 32ms burst [Q: empty]
time 52447ms: Process E completed a CPU burst; 32 bursts to go [Q: empty]
time 52447ms: Process E switching out of CPU; will block on I/O until time 53159ms [Q: empty]
time 52586ms: Process G completed I/O; added to ready queue [Q: G]
time 52588ms: Process G started using the CPU for 93ms burst [Q: empty]
time 52613ms: Process H completed I/O; added to ready queue [Q: H]
time 52669ms: Process B completed I/O; added to ready queue [Q: H B]
time 52681ms: Process G completed a CPU burst; 2 bursts to go [Q: H B]
time 52681ms: Process G switching out of CPU; will block on I/O until time 54013ms [Q: H B]
time 52685ms: Process H started using the CPU for 151ms burst [Q: B]
time 52729ms: Process F completed I/O; added to ready queue [Q: B F]
time 52836ms: Process H completed a CPU burst; 40 bursts to go [Q: B F]
time 52836ms: Process H switching out of CPU; will block on I/O until time 53068ms [Q: B F]
time 52840ms: Process B started using the CPU for 65ms burst [Q: F]
time 52905ms: Process B completed a CPU burst; 13 bursts to go [Q: F]
time 52905ms: Process B switching out of CPU; will block on I/O until time 53477ms [Q: F]
time 52909ms: Process F started using the CPU for 2ms burst [Q: empty]
time 52911ms: Process F completed a CPU burst; 12 bursts to go [Q: empty]
time 52911ms: Process F switching out of CPU; will block on I/O until time 53163ms [Q: empty]
time 53068ms: Process H completed I/O; added to ready queue [Q: H]
time 53070ms: Process H started using the CPU for 135ms burst [Q: empty]
time 53159ms: Process E completed I/O; added to ready queue [Q: E]
time 53163ms: Process F completed I/O; added to ready queue [Q: E F]
time 53205ms: Process H completed a CPU burst; 39 bursts to go [Q: E F]
time 53205ms: Process H switching out of CPU; will block on I/O until time 53397ms [Q: E F]
time 53209ms: Process E started using the CPU for 2ms burst [Q: F]
time 53211ms: Process E completed a CPU burst; 31 bursts to go [Q: F]
time 53211ms: Process E switching out of CPU; will block on I/O until time 55163ms [Q: F]
time 53215ms: Process F started using the CPU for 55ms burst [Q: empty]
time 53270ms: Process F completed a CPU burst; 11 bursts to go [Q: empty]
time 53270ms: Process F switching out of CPU; will block on I/O until time 54082ms [Q: empty]
time 53397ms: Process H completed I/O; added to ready queue [Q: H]
time 53399ms: Process H started using the CPU for 110ms burst [Q: empty]
time 53477ms: Process B completed I/O; added to ready queue [Q: B]
time 53509ms: Process H completed a CPU burst; 38 bursts to go [Q: B]
time 53509ms: Process H switching out of CPU; will block on I/O until time 55521ms [Q: B]
time 53513ms: Process B started using the CPU for 39ms burst [Q: empty]
time 53552ms: Process B completed a CPU burst; 12 bursts to go [Q: empty]
time 53552ms: Process B switching out of CPU; will block on I/O until time 54624ms [Q: empty]
time 53862ms: Process D completed I/O; added to ready queue [Q: D]
time 53864ms: Process D started using the CPU for 48ms burst [Q: empty]
time 53912ms: Process D completed a CPU burst; 41 bursts to go [Q: empty]
time 53912ms: Process D switching out of CPU; will block on I/O until time 54294ms [Q: empty]
time 54013ms: Process G completed I/O; added to ready queue [Q: G]
time 54015ms: Process G started using the CPU for 123ms burst [Q: empty]
time 54082ms: Process F completed I/O; added to ready queue [Q: F]
time 54138ms: Process G completed a CPU burst; 1 burst to go [Q: F]
time 54138ms: Process G switching out of CPU; will block on I/O until time 55360ms [Q: F]
time 54142ms: Process F started using the CPU for 91ms burst [Q: empty]
time 54233ms: Process F completed a CPU burst; 10 bursts to go [Q: empty]
time 54233ms: Process F switching out of CPU; will block on I/O until time 54605ms [Q: empty]
time 54294ms: Process D completed I/O; added to ready queue [Q: D]
time 54296ms: Process D started using the CPU for 144ms burst [Q: empty]
time 54440ms: Process D completed a CPU burst; 40 bursts to go [Q: empty]
time 54440ms: Process D switching out of CPU; will block on I/O until time 55722ms [Q: empty]
time 54605ms: Process F completed I/O; added to ready queue [Q: F]
time 54607ms: Process F started using the CPU for 35ms burst [Q: empty]
time 54624ms: Process B completed I/O; added to ready queue [Q: B]
